Started at 2020-12-08 21:02:09
 
 -------------- celery@localhost.localdomain v5.0.2 (singularity)
--- ***** ----- 
-- ******* ---- Linux-5.8.11-200.fc32.x86_64-x86_64-with-glibc2.2.5 2020-12-08 21:02:09
- *** --- * --- 
- ** ---------- [config]
- ** ---------- .> app:         backend.main:0x7f04c1ffc190
- ** ---------- .> transport:   redis://localhost:6379//
- ** ---------- .> results:     redis://localhost:6379/
- *** --- * --- .> concurrency: 8 (prefork)
-- ******* ---- .> task events: OFF (enable -E to monitor tasks in this worker)
--- ***** ----- 
 -------------- [queues]
                .> celery           exchange=celery(direct) key=celery
                

[tasks]
  . backend.main.tasks.accumulate_time

[2020-12-08 21:02:09,911: INFO/MainProcess] Connected to redis://localhost:6379//
[2020-12-08 21:02:09,916: INFO/MainProcess] mingle: searching for neighbors
[2020-12-08 21:02:10,931: INFO/MainProcess] mingle: all alone
[2020-12-08 21:02:10,959: INFO/MainProcess] celery@localhost.localdomain ready.
[2020-12-08 21:02:11,122: INFO/MainProcess] Received task: backend.main.tasks.accumulate_time[a43c0942-fb5d-4a98-83e4-b8540c50fda2]  
[2020-12-08 21:02:11,126: INFO/MainProcess] Received task: backend.main.tasks.accumulate_time[3f76c31a-26ba-4114-b96d-4b5973b474ba]  
[2020-12-08 21:02:11,129: INFO/MainProcess] Received task: backend.main.tasks.accumulate_time[9b8d1a28-3718-4b84-853e-5ccf6fcc23f6]  
[2020-12-08 21:02:11,135: INFO/MainProcess] Received task: backend.main.tasks.accumulate_time[7ac3e2ea-4350-4e96-ae28-84331343b919]  
[2020-12-08 21:02:11,143: INFO/MainProcess] Received task: backend.main.tasks.accumulate_time[f17d8337-abb8-4479-bad7-0c99f071c12d]  
[2020-12-08 21:02:11,188: INFO/ForkPoolWorker-1] Task backend.main.tasks.accumulate_time[9b8d1a28-3718-4b84-853e-5ccf6fcc23f6] succeeded in 0.05076498100061144s: None
[2020-12-08 21:03:02,415: INFO/MainProcess] Received task: backend.main.tasks.accumulate_time[50384fc1-1fda-4cdb-9db0-bc89837cba10]  
[2020-12-08 21:03:05,961: INFO/MainProcess] Received task: backend.main.tasks.accumulate_time[09d0e713-417a-4d62-b055-37424e4ad617]  

worker: Hitting Ctrl+C again will terminate all running tasks!

worker: Warm shutdown (MainProcess)

worker: Cold shutdown (MainProcess)

worker: Cold shutdown (MainProcess)

Restarting celery worker (/usr/local/bin/celery -A celery_worker.celery worker --loglevel info)

Restarting celery worker (/usr/local/bin/celery -A celery_worker.celery worker --loglevel info)
[2020-12-08 21:43:42,237: ERROR/MainProcess] Process 'ForkPoolWorker-8' pid:10413 exited with 'signal 1 (SIGHUP)'
[2020-12-08 21:43:42,247: ERROR/MainProcess] Process 'ForkPoolWorker-7' pid:10412 exited with 'signal 1 (SIGHUP)'
[2020-12-08 21:43:42,258: ERROR/MainProcess] Process 'ForkPoolWorker-3' pid:10408 exited with 'signal 1 (SIGHUP)'
[2020-12-08 21:43:42,269: ERROR/MainProcess] Process 'ForkPoolWorker-2' pid:10407 exited with 'signal 1 (SIGHUP)'
[2020-12-08 21:43:42,279: ERROR/MainProcess] Process 'ForkPoolWorker-1' pid:10406 exited with 'signal 1 (SIGHUP)'
[2020-12-08 21:43:42,301: ERROR/MainProcess] Task handler raised error: WorkerLostError('Worker exited prematurely: signal 1 (SIGHUP).')
Traceback (most recent call last):
  File "/usr/local/lib/python3.8/site-packages/celery/worker/worker.py", line 203, in start
    self.blueprint.start(self)
  File "/usr/local/lib/python3.8/site-packages/celery/bootsteps.py", line 116, in start
    step.start(parent)
  File "/usr/local/lib/python3.8/site-packages/celery/bootsteps.py", line 365, in start
    return self.obj.start()
  File "/usr/local/lib/python3.8/site-packages/celery/worker/consumer/consumer.py", line 311, in start
    blueprint.start(self)
  File "/usr/local/lib/python3.8/site-packages/celery/bootsteps.py", line 116, in start
    step.start(parent)
  File "/usr/local/lib/python3.8/site-packages/celery/worker/consumer/consumer.py", line 592, in start
    c.loop(*c.loop_args())
  File "/usr/local/lib/python3.8/site-packages/celery/worker/loops.py", line 72, in asynloop
    state.maybe_shutdown()
  File "/usr/local/lib/python3.8/site-packages/celery/worker/state.py", line 77, in maybe_shutdown
    raise WorkerShutdown(should_stop)
celery.exceptions.WorkerShutdown: 1

During handling of the above exception, another exception occurred:

Traceback (most recent call last):
  File "/usr/local/lib/python3.8/site-packages/billiard/pool.py", line 1265, in mark_as_worker_lost
    raise WorkerLostError(
billiard.exceptions.WorkerLostError: Worker exited prematurely: signal 1 (SIGHUP).
[2020-12-08 21:43:42,304: ERROR/MainProcess] Task handler raised error: WorkerLostError('Worker exited prematurely: signal 1 (SIGHUP).')
Traceback (most recent call last):
  File "/usr/local/lib/python3.8/site-packages/celery/worker/worker.py", line 203, in start
    self.blueprint.start(self)
  File "/usr/local/lib/python3.8/site-packages/celery/bootsteps.py", line 116, in start
    step.start(parent)
  File "/usr/local/lib/python3.8/site-packages/celery/bootsteps.py", line 365, in start
    return self.obj.start()
  File "/usr/local/lib/python3.8/site-packages/celery/worker/consumer/consumer.py", line 311, in start
    blueprint.start(self)
  File "/usr/local/lib/python3.8/site-packages/celery/bootsteps.py", line 116, in start
    step.start(parent)
  File "/usr/local/lib/python3.8/site-packages/celery/worker/consumer/consumer.py", line 592, in start
    c.loop(*c.loop_args())
  File "/usr/local/lib/python3.8/site-packages/celery/worker/loops.py", line 72, in asynloop
    state.maybe_shutdown()
  File "/usr/local/lib/python3.8/site-packages/celery/worker/state.py", line 77, in maybe_shutdown
    raise WorkerShutdown(should_stop)
celery.exceptions.WorkerShutdown: 1

During handling of the above exception, another exception occurred:

Traceback (most recent call last):
  File "/usr/local/lib/python3.8/site-packages/billiard/pool.py", line 1265, in mark_as_worker_lost
    raise WorkerLostError(
billiard.exceptions.WorkerLostError: Worker exited prematurely: signal 1 (SIGHUP).
[2020-12-08 21:43:42,307: ERROR/MainProcess] Task handler raised error: WorkerLostError('Worker exited prematurely: signal 1 (SIGHUP).')
Traceback (most recent call last):
  File "/usr/local/lib/python3.8/site-packages/celery/worker/worker.py", line 203, in start
    self.blueprint.start(self)
  File "/usr/local/lib/python3.8/site-packages/celery/bootsteps.py", line 116, in start
    step.start(parent)
  File "/usr/local/lib/python3.8/site-packages/celery/bootsteps.py", line 365, in start
    return self.obj.start()
  File "/usr/local/lib/python3.8/site-packages/celery/worker/consumer/consumer.py", line 311, in start
    blueprint.start(self)
  File "/usr/local/lib/python3.8/site-packages/celery/bootsteps.py", line 116, in start
    step.start(parent)
  File "/usr/local/lib/python3.8/site-packages/celery/worker/consumer/consumer.py", line 592, in start
    c.loop(*c.loop_args())
  File "/usr/local/lib/python3.8/site-packages/celery/worker/loops.py", line 72, in asynloop
    state.maybe_shutdown()
  File "/usr/local/lib/python3.8/site-packages/celery/worker/state.py", line 77, in maybe_shutdown
    raise WorkerShutdown(should_stop)
celery.exceptions.WorkerShutdown: 1

During handling of the above exception, another exception occurred:

Traceback (most recent call last):
  File "/usr/local/lib/python3.8/site-packages/billiard/pool.py", line 1265, in mark_as_worker_lost
    raise WorkerLostError(
billiard.exceptions.WorkerLostError: Worker exited prematurely: signal 1 (SIGHUP).
[2020-12-08 21:43:42,311: ERROR/MainProcess] Task handler raised error: WorkerLostError('Worker exited prematurely: signal 1 (SIGHUP).')
Traceback (most recent call last):
  File "/usr/local/lib/python3.8/site-packages/celery/worker/worker.py", line 203, in start
    self.blueprint.start(self)
  File "/usr/local/lib/python3.8/site-packages/celery/bootsteps.py", line 116, in start
    step.start(parent)
  File "/usr/local/lib/python3.8/site-packages/celery/bootsteps.py", line 365, in start
    return self.obj.start()
  File "/usr/local/lib/python3.8/site-packages/celery/worker/consumer/consumer.py", line 311, in start
    blueprint.start(self)
  File "/usr/local/lib/python3.8/site-packages/celery/bootsteps.py", line 116, in start
    step.start(parent)
  File "/usr/local/lib/python3.8/site-packages/celery/worker/consumer/consumer.py", line 592, in start
    c.loop(*c.loop_args())
  File "/usr/local/lib/python3.8/site-packages/celery/worker/loops.py", line 72, in asynloop
    state.maybe_shutdown()
  File "/usr/local/lib/python3.8/site-packages/celery/worker/state.py", line 77, in maybe_shutdown
    raise WorkerShutdown(should_stop)
celery.exceptions.WorkerShutdown: 1

During handling of the above exception, another exception occurred:

Traceback (most recent call last):
  File "/usr/local/lib/python3.8/site-packages/billiard/pool.py", line 1265, in mark_as_worker_lost
    raise WorkerLostError(
billiard.exceptions.WorkerLostError: Worker exited prematurely: signal 1 (SIGHUP).
[2020-12-08 21:43:42,314: ERROR/MainProcess] Task handler raised error: WorkerLostError('Worker exited prematurely: signal 1 (SIGHUP).')
Traceback (most recent call last):
  File "/usr/local/lib/python3.8/site-packages/celery/worker/worker.py", line 203, in start
    self.blueprint.start(self)
  File "/usr/local/lib/python3.8/site-packages/celery/bootsteps.py", line 116, in start
    step.start(parent)
  File "/usr/local/lib/python3.8/site-packages/celery/bootsteps.py", line 365, in start
    return self.obj.start()
  File "/usr/local/lib/python3.8/site-packages/celery/worker/consumer/consumer.py", line 311, in start
    blueprint.start(self)
  File "/usr/local/lib/python3.8/site-packages/celery/bootsteps.py", line 116, in start
    step.start(parent)
  File "/usr/local/lib/python3.8/site-packages/celery/worker/consumer/consumer.py", line 592, in start
    c.loop(*c.loop_args())
  File "/usr/local/lib/python3.8/site-packages/celery/worker/loops.py", line 72, in asynloop
    state.maybe_shutdown()
  File "/usr/local/lib/python3.8/site-packages/celery/worker/state.py", line 77, in maybe_shutdown
    raise WorkerShutdown(should_stop)
celery.exceptions.WorkerShutdown: 1

During handling of the above exception, another exception occurred:

Traceback (most recent call last):
  File "/usr/local/lib/python3.8/site-packages/billiard/pool.py", line 1265, in mark_as_worker_lost
    raise WorkerLostError(
billiard.exceptions.WorkerLostError: Worker exited prematurely: signal 1 (SIGHUP).
[2020-12-08 21:43:42,817: ERROR/MainProcess] Process 'ForkPoolWorker-4' pid:10409 exited with 'exitcode 70'
[2020-12-08 21:43:42,830: ERROR/MainProcess] Task handler raised error: WorkerLostError('Worker exited prematurely: exitcode 70.')
Traceback (most recent call last):
  File "/usr/local/lib/python3.8/site-packages/celery/worker/worker.py", line 203, in start
    self.blueprint.start(self)
  File "/usr/local/lib/python3.8/site-packages/celery/bootsteps.py", line 116, in start
    step.start(parent)
  File "/usr/local/lib/python3.8/site-packages/celery/bootsteps.py", line 365, in start
    return self.obj.start()
  File "/usr/local/lib/python3.8/site-packages/celery/worker/consumer/consumer.py", line 311, in start
    blueprint.start(self)
  File "/usr/local/lib/python3.8/site-packages/celery/bootsteps.py", line 116, in start
    step.start(parent)
  File "/usr/local/lib/python3.8/site-packages/celery/worker/consumer/consumer.py", line 592, in start
    c.loop(*c.loop_args())
  File "/usr/local/lib/python3.8/site-packages/celery/worker/loops.py", line 72, in asynloop
    state.maybe_shutdown()
  File "/usr/local/lib/python3.8/site-packages/celery/worker/state.py", line 77, in maybe_shutdown
    raise WorkerShutdown(should_stop)
celery.exceptions.WorkerShutdown: 1

During handling of the above exception, another exception occurred:

Traceback (most recent call last):
  File "/usr/local/lib/python3.8/site-packages/billiard/pool.py", line 1265, in mark_as_worker_lost
    raise WorkerLostError(
billiard.exceptions.WorkerLostError: Worker exited prematurely: exitcode 70.
Started at 2020-12-08 21:48:28
 
 -------------- celery@localhost.localdomain v5.0.2 (singularity)
--- ***** ----- 
-- ******* ---- Linux-5.8.11-200.fc32.x86_64-x86_64-with-glibc2.2.5 2020-12-08 21:48:29
- *** --- * --- 
- ** ---------- [config]
- ** ---------- .> app:         backend.main:0x7fc34a41c6a0
- ** ---------- .> transport:   redis://localhost:6379//
- ** ---------- .> results:     redis://localhost:6379/
- *** --- * --- .> concurrency: 8 (prefork)
-- ******* ---- .> task events: OFF (enable -E to monitor tasks in this worker)
--- ***** ----- 
 -------------- [queues]
                .> celery           exchange=celery(direct) key=celery
                

[tasks]
  . backend.main.tasks.accumulate_time

[2020-12-08 21:48:29,239: INFO/MainProcess] Connected to redis://localhost:6379//
[2020-12-08 21:48:29,245: INFO/MainProcess] mingle: searching for neighbors
[2020-12-08 21:48:30,259: INFO/MainProcess] mingle: all alone
[2020-12-08 21:48:30,283: INFO/MainProcess] celery@localhost.localdomain ready.
[2020-12-08 21:49:48,946: INFO/MainProcess] Received task: backend.main.tasks.accumulate_time[8052a123-fe10-4115-8ff1-9af3868365e7]  
[2020-12-08 21:49:57,015: WARNING/ForkPoolWorker-7] PV disconnected!
[2020-12-08 21:49:57,027: ERROR/ForkPoolWorker-7] Task backend.main.tasks.accumulate_time[8052a123-fe10-4115-8ff1-9af3868365e7] raised unexpected: UnboundLocalError("local variable 'has_current' referenced before assignment")
Traceback (most recent call last):
  File "/usr/local/lib/python3.8/site-packages/celery/app/trace.py", line 409, in trace_task
    R = retval = fun(*args, **kwargs)
  File "/home/linac/commissioning/lattice-setting/backend/main/celery_utils.py", line 9, in __call__
    call_res = TaskBase.__call__(self, *args, **kwargs)
  File "/usr/local/lib/python3.8/site-packages/celery/app/trace.py", line 701, in __protected_call__
    return self.run(*args, **kwargs)
  File "/home/linac/commissioning/lattice-setting/backend/main/tasks.py", line 165, in accumulate_time
    has_current, duty_factor,
UnboundLocalError: local variable 'has_current' referenced before assignment

worker: Warm shutdown (MainProcess)
Started at 2020-12-10 11:06:22
 
 -------------- celery@localhost.localdomain v5.0.2 (singularity)
--- ***** ----- 
-- ******* ---- Linux-5.8.11-200.fc32.x86_64-x86_64-with-glibc2.2.5 2020-12-10 11:06:22
- *** --- * --- 
- ** ---------- [config]
- ** ---------- .> app:         backend.main:0x7faae4918850
- ** ---------- .> transport:   redis://localhost:6379//
- ** ---------- .> results:     redis://localhost:6379/
- *** --- * --- .> concurrency: 8 (prefork)
-- ******* ---- .> task events: OFF (enable -E to monitor tasks in this worker)
--- ***** ----- 
 -------------- [queues]
                .> celery           exchange=celery(direct) key=celery
                

[tasks]
  . backend.main.tasks.accumulate_time

[2020-12-10 11:06:23,135: INFO/MainProcess] Connected to redis://localhost:6379//
[2020-12-10 11:06:23,141: INFO/MainProcess] mingle: searching for neighbors
[2020-12-10 11:06:24,154: INFO/MainProcess] mingle: all alone
[2020-12-10 11:06:24,165: INFO/MainProcess] celery@localhost.localdomain ready.
[2020-12-10 11:28:46,118: INFO/MainProcess] Received task: backend.main.tasks.accumulate_time[f6df2bef-64f7-4ae9-a9a4-0d1fb7c878e0]  
[2020-12-10 20:30:02,419: ERROR/ForkPoolWorker-7] Task backend.main.tasks.accumulate_time[f6df2bef-64f7-4ae9-a9a4-0d1fb7c878e0] raised unexpected: StatementError("(builtins.ValueError) could not convert string to float: 'None'")
Traceback (most recent call last):
  File "/usr/local/lib64/python3.8/site-packages/sqlalchemy/engine/base.py", line 1204, in _execute_context
    context = constructor(dialect, self, conn, *args)
  File "/usr/local/lib64/python3.8/site-packages/sqlalchemy/engine/default.py", line 839, in _init_compiled
    param.append(processors[key](compiled_params[key]))
ValueError: could not convert string to float: 'None'

The above exception was the direct cause of the following exception:

Traceback (most recent call last):
  File "/usr/local/lib/python3.8/site-packages/celery/app/trace.py", line 409, in trace_task
    R = retval = fun(*args, **kwargs)
  File "/home/linac/commissioning/lattice-setting/backend/main/celery_utils.py", line 9, in __call__
    call_res = TaskBase.__call__(self, *args, **kwargs)
  File "/usr/local/lib/python3.8/site-packages/celery/app/trace.py", line 701, in __protected_call__
    return self.run(*args, **kwargs)
  File "/home/linac/commissioning/lattice-setting/backend/main/tasks.py", line 163, in accumulate_time
    prev_time, timing_dict = timing_add_needed(current_time, prev_time,
  File "/home/linac/commissioning/lattice-setting/backend/main/tasks.py", line 101, in timing_add_needed
    save_timing(timing_dict)
  File "/home/linac/commissioning/lattice-setting/backend/main/tasks.py", line 37, in save_timing
    db.session.commit()
  File "/usr/local/lib64/python3.8/site-packages/sqlalchemy/orm/scoping.py", line 163, in do
    return getattr(self.registry(), name)(*args, **kwargs)
  File "/usr/local/lib64/python3.8/site-packages/sqlalchemy/orm/session.py", line 1042, in commit
    self.transaction.commit()
  File "/usr/local/lib64/python3.8/site-packages/sqlalchemy/orm/session.py", line 504, in commit
    self._prepare_impl()
  File "/usr/local/lib64/python3.8/site-packages/sqlalchemy/orm/session.py", line 483, in _prepare_impl
    self.session.flush()
  File "/usr/local/lib64/python3.8/site-packages/sqlalchemy/orm/session.py", line 2536, in flush
    self._flush(objects)
  File "/usr/local/lib64/python3.8/site-packages/sqlalchemy/orm/session.py", line 2678, in _flush
    transaction.rollback(_capture_exception=True)
  File "/usr/local/lib64/python3.8/site-packages/sqlalchemy/util/langhelpers.py", line 68, in __exit__
    compat.raise_(
  File "/usr/local/lib64/python3.8/site-packages/sqlalchemy/util/compat.py", line 182, in raise_
    raise exception
  File "/usr/local/lib64/python3.8/site-packages/sqlalchemy/orm/session.py", line 2638, in _flush
    flush_context.execute()
  File "/usr/local/lib64/python3.8/site-packages/sqlalchemy/orm/unitofwork.py", line 422, in execute
    rec.execute(self)
  File "/usr/local/lib64/python3.8/site-packages/sqlalchemy/orm/unitofwork.py", line 586, in execute
    persistence.save_obj(
  File "/usr/local/lib64/python3.8/site-packages/sqlalchemy/orm/persistence.py", line 239, in save_obj
    _emit_insert_statements(
  File "/usr/local/lib64/python3.8/site-packages/sqlalchemy/orm/persistence.py", line 1135, in _emit_insert_statements
    result = cached_connections[connection].execute(
  File "/usr/local/lib64/python3.8/site-packages/sqlalchemy/engine/base.py", line 1011, in execute
    return meth(self, multiparams, params)
  File "/usr/local/lib64/python3.8/site-packages/sqlalchemy/sql/elements.py", line 298, in _execute_on_connection
    return connection._execute_clauseelement(self, multiparams, params)
  File "/usr/local/lib64/python3.8/site-packages/sqlalchemy/engine/base.py", line 1124, in _execute_clauseelement
    ret = self._execute_context(
  File "/usr/local/lib64/python3.8/site-packages/sqlalchemy/engine/base.py", line 1206, in _execute_context
    self._handle_dbapi_exception(
  File "/usr/local/lib64/python3.8/site-packages/sqlalchemy/engine/base.py", line 1510, in _handle_dbapi_exception
    util.raise_(
  File "/usr/local/lib64/python3.8/site-packages/sqlalchemy/util/compat.py", line 182, in raise_
    raise exception
  File "/usr/local/lib64/python3.8/site-packages/sqlalchemy/engine/base.py", line 1204, in _execute_context
    context = constructor(dialect, self, conn, *args)
  File "/usr/local/lib64/python3.8/site-packages/sqlalchemy/engine/default.py", line 839, in _init_compiled
    param.append(processors[key](compiled_params[key]))
sqlalchemy.exc.StatementError: (builtins.ValueError) could not convert string to float: 'None'
[SQL: INSERT INTO timing (timestamp, dutyfactor, times, acct1, acct2, acct3, acct4) VALUES (?, ?, ?, ?, ?, ?, ?)]
[parameters: [{'dutyfactor': 'None', 'acct2': 5.829647920917768, 'acct1': 6.204711610307025, 'acct4': 1.0703633292565333, 'times': 16597.893134832382, 'acct3': 5.83108423601726}]]

worker: Warm shutdown (MainProcess)
Started at 2020-12-11 09:27:02
 
 -------------- celery@localhost.localdomain v5.0.2 (singularity)
--- ***** ----- 
-- ******* ---- Linux-5.8.11-200.fc32.x86_64-x86_64-with-glibc2.2.5 2020-12-11 09:27:02
- *** --- * --- 
- ** ---------- [config]
- ** ---------- .> app:         backend.main:0x7f09e9720850
- ** ---------- .> transport:   redis://localhost:6379//
- ** ---------- .> results:     redis://localhost:6379/
- *** --- * --- .> concurrency: 8 (prefork)
-- ******* ---- .> task events: OFF (enable -E to monitor tasks in this worker)
--- ***** ----- 
 -------------- [queues]
                .> celery           exchange=celery(direct) key=celery
                

[tasks]
  . backend.main.tasks.accumulate_time

[2020-12-11 09:27:03,010: INFO/MainProcess] Connected to redis://localhost:6379//
[2020-12-11 09:27:03,016: INFO/MainProcess] mingle: searching for neighbors
[2020-12-11 09:27:04,031: INFO/MainProcess] mingle: all alone
[2020-12-11 09:27:04,054: INFO/MainProcess] celery@localhost.localdomain ready.
[2020-12-11 09:27:18,671: INFO/MainProcess] Received task: backend.main.tasks.accumulate_time[d65f03e2-37b4-432d-9963-51fe84128797]  
[2020-12-11 09:28:46,734: INFO/ForkPoolWorker-7] Task backend.main.tasks.accumulate_time[d65f03e2-37b4-432d-9963-51fe84128797] succeeded in 88.0624448620074s: None

worker: Warm shutdown (MainProcess)
Started at 2020-12-11 09:47:29
 
 -------------- celery@localhost.localdomain v5.0.2 (singularity)
--- ***** ----- 
-- ******* ---- Linux-5.8.11-200.fc32.x86_64-x86_64-with-glibc2.2.5 2020-12-11 09:47:30
- *** --- * --- 
- ** ---------- [config]
- ** ---------- .> app:         backend.main:0x7f474dd16850
- ** ---------- .> transport:   redis://localhost:6379//
- ** ---------- .> results:     redis://localhost:6379/
- *** --- * --- .> concurrency: 8 (prefork)
-- ******* ---- .> task events: OFF (enable -E to monitor tasks in this worker)
--- ***** ----- 
 -------------- [queues]
                .> celery           exchange=celery(direct) key=celery
                

[tasks]
  . backend.main.tasks.accumulate_time

[2020-12-11 09:47:30,276: ERROR/MainProcess] consumer: Cannot connect to redis://localhost:6379//: Error 111 connecting to localhost:6379. Connection refused..
Trying again in 2.00 seconds... (1/100)

[2020-12-11 09:47:32,280: ERROR/MainProcess] consumer: Cannot connect to redis://localhost:6379//: Error 111 connecting to localhost:6379. Connection refused..
Trying again in 4.00 seconds... (2/100)

[2020-12-11 09:47:36,288: INFO/MainProcess] Connected to redis://localhost:6379//
[2020-12-11 09:47:36,296: INFO/MainProcess] mingle: searching for neighbors
[2020-12-11 09:47:37,310: INFO/MainProcess] mingle: all alone
[2020-12-11 09:47:37,317: INFO/MainProcess] celery@localhost.localdomain ready.
[2020-12-11 09:50:41,214: INFO/MainProcess] Received task: backend.main.tasks.accumulate_time[a0d492e0-772e-4fc5-adca-09d04e35c6e7]  
[2020-12-11 09:54:18,383: INFO/ForkPoolWorker-7] Task backend.main.tasks.accumulate_time[a0d492e0-772e-4fc5-adca-09d04e35c6e7] succeeded in 216.715142043s: None
[2020-12-11 09:55:31,843: INFO/MainProcess] Received task: backend.main.tasks.accumulate_time[42e35d77-ede8-4e9d-bd61-48152c11d080]  
[2020-12-11 09:57:20,920: INFO/ForkPoolWorker-7] Task backend.main.tasks.accumulate_time[42e35d77-ede8-4e9d-bd61-48152c11d080] succeeded in 109.07668827500004s: None
[2020-12-11 09:57:27,262: INFO/MainProcess] Received task: backend.main.tasks.accumulate_time[12bd56a9-9cdd-4b27-a345-28c583a68607]  
[2020-12-11 09:57:49,285: INFO/ForkPoolWorker-7] Task backend.main.tasks.accumulate_time[12bd56a9-9cdd-4b27-a345-28c583a68607] succeeded in 22.020516843999985s: None

worker: Warm shutdown (MainProcess)
Started at 2020-12-11 10:12:02
 
 -------------- celery@localhost.localdomain v5.0.2 (singularity)
--- ***** ----- 
-- ******* ---- Linux-5.8.11-200.fc32.x86_64-x86_64-with-glibc2.2.5 2020-12-11 10:12:03
- *** --- * --- 
- ** ---------- [config]
- ** ---------- .> app:         backend.main:0x7f87b802d850
- ** ---------- .> transport:   redis://localhost:6379//
- ** ---------- .> results:     redis://localhost:6379/
- *** --- * --- .> concurrency: 8 (prefork)
-- ******* ---- .> task events: OFF (enable -E to monitor tasks in this worker)
--- ***** ----- 
 -------------- [queues]
                .> celery           exchange=celery(direct) key=celery
                

[tasks]
  . backend.main.tasks.accumulate_time

[2020-12-11 10:12:03,361: INFO/MainProcess] Connected to redis://localhost:6379//
[2020-12-11 10:12:03,367: INFO/MainProcess] mingle: searching for neighbors
[2020-12-11 10:12:04,382: INFO/MainProcess] mingle: all alone
[2020-12-11 10:12:04,406: INFO/MainProcess] celery@localhost.localdomain ready.
[2020-12-11 10:12:10,980: INFO/MainProcess] Received task: backend.main.tasks.accumulate_time[6d9c0233-e874-425c-937b-a0136daaa970]  
[2020-12-11 10:12:11,018: WARNING/ForkPoolWorker-7] 0.002
Unexpected problem with CA circuit to server "192.168.6.106:5064" was "Connection timed out" - disconnecting
CA.Client.Exception...............................................
    Warning: "Virtual circuit disconnect"
    Context: "192.168.6.106:5064"
    Source File: ../cac.cpp line 1237
    Current Time: Fri Dec 11 2020 12:24:54.795189578
..................................................................
Unexpected problem with CA circuit to server "192.168.6.106:5064" was "Connection timed out" - disconnecting
CA.Client.Exception...............................................
    Warning: "Virtual circuit disconnect"
    Context: "192.168.6.106:5064"
    Source File: ../cac.cpp line 1237
    Current Time: Fri Dec 11 2020 15:36:07.691000338
..................................................................
Unexpected problem with CA circuit to server "192.168.6.106:5064" was "Connection timed out" - disconnecting
CA.Client.Exception...............................................
    Warning: "Virtual circuit disconnect"
    Context: "192.168.6.106:5064"
    Source File: ../cac.cpp line 1237
    Current Time: Fri Dec 11 2020 17:51:34.155093100
..................................................................
Unexpected problem with CA circuit to server "192.168.6.106:5064" was "Connection timed out" - disconnecting
CA.Client.Exception...............................................
    Warning: "Virtual circuit disconnect"
    Context: "192.168.6.106:5064"
    Source File: ../cac.cpp line 1237
    Current Time: Fri Dec 11 2020 20:07:00.619049536
..................................................................
[2020-12-11 20:30:00,399: ERROR/ForkPoolWorker-7] Task backend.main.tasks.accumulate_time[6d9c0233-e874-425c-937b-a0136daaa970] raised unexpected: StatementError("(builtins.ValueError) could not convert string to float: 'None'")
Traceback (most recent call last):
  File "/usr/local/lib64/python3.8/site-packages/sqlalchemy/engine/base.py", line 1204, in _execute_context
    context = constructor(dialect, self, conn, *args)
  File "/usr/local/lib64/python3.8/site-packages/sqlalchemy/engine/default.py", line 839, in _init_compiled
    param.append(processors[key](compiled_params[key]))
ValueError: could not convert string to float: 'None'

The above exception was the direct cause of the following exception:

Traceback (most recent call last):
  File "/usr/local/lib/python3.8/site-packages/celery/app/trace.py", line 409, in trace_task
    R = retval = fun(*args, **kwargs)
  File "/home/linac/commissioning/lattice-setting/backend/main/celery_utils.py", line 9, in __call__
    call_res = TaskBase.__call__(self, *args, **kwargs)
  File "/usr/local/lib/python3.8/site-packages/celery/app/trace.py", line 701, in __protected_call__
    return self.run(*args, **kwargs)
  File "/home/linac/commissioning/lattice-setting/backend/main/tasks.py", line 164, in accumulate_time
    prev_time, timing_dict = timing_add_needed(current_time, prev_time,
  File "/home/linac/commissioning/lattice-setting/backend/main/tasks.py", line 101, in timing_add_needed
    save_timing(timing_dict)
  File "/home/linac/commissioning/lattice-setting/backend/main/tasks.py", line 37, in save_timing
    db.session.commit()
  File "/usr/local/lib64/python3.8/site-packages/sqlalchemy/orm/scoping.py", line 163, in do
    return getattr(self.registry(), name)(*args, **kwargs)
  File "/usr/local/lib64/python3.8/site-packages/sqlalchemy/orm/session.py", line 1042, in commit
    self.transaction.commit()
  File "/usr/local/lib64/python3.8/site-packages/sqlalchemy/orm/session.py", line 504, in commit
    self._prepare_impl()
  File "/usr/local/lib64/python3.8/site-packages/sqlalchemy/orm/session.py", line 483, in _prepare_impl
    self.session.flush()
  File "/usr/local/lib64/python3.8/site-packages/sqlalchemy/orm/session.py", line 2536, in flush
    self._flush(objects)
  File "/usr/local/lib64/python3.8/site-packages/sqlalchemy/orm/session.py", line 2678, in _flush
    transaction.rollback(_capture_exception=True)
  File "/usr/local/lib64/python3.8/site-packages/sqlalchemy/util/langhelpers.py", line 68, in __exit__
    compat.raise_(
  File "/usr/local/lib64/python3.8/site-packages/sqlalchemy/util/compat.py", line 182, in raise_
    raise exception
  File "/usr/local/lib64/python3.8/site-packages/sqlalchemy/orm/session.py", line 2638, in _flush
    flush_context.execute()
  File "/usr/local/lib64/python3.8/site-packages/sqlalchemy/orm/unitofwork.py", line 422, in execute
    rec.execute(self)
  File "/usr/local/lib64/python3.8/site-packages/sqlalchemy/orm/unitofwork.py", line 586, in execute
    persistence.save_obj(
  File "/usr/local/lib64/python3.8/site-packages/sqlalchemy/orm/persistence.py", line 239, in save_obj
    _emit_insert_statements(
  File "/usr/local/lib64/python3.8/site-packages/sqlalchemy/orm/persistence.py", line 1135, in _emit_insert_statements
    result = cached_connections[connection].execute(
  File "/usr/local/lib64/python3.8/site-packages/sqlalchemy/engine/base.py", line 1011, in execute
    return meth(self, multiparams, params)
  File "/usr/local/lib64/python3.8/site-packages/sqlalchemy/sql/elements.py", line 298, in _execute_on_connection
    return connection._execute_clauseelement(self, multiparams, params)
  File "/usr/local/lib64/python3.8/site-packages/sqlalchemy/engine/base.py", line 1124, in _execute_clauseelement
    ret = self._execute_context(
  File "/usr/local/lib64/python3.8/site-packages/sqlalchemy/engine/base.py", line 1206, in _execute_context
    self._handle_dbapi_exception(
  File "/usr/local/lib64/python3.8/site-packages/sqlalchemy/engine/base.py", line 1510, in _handle_dbapi_exception
    util.raise_(
  File "/usr/local/lib64/python3.8/site-packages/sqlalchemy/util/compat.py", line 182, in raise_
    raise exception
  File "/usr/local/lib64/python3.8/site-packages/sqlalchemy/engine/base.py", line 1204, in _execute_context
    context = constructor(dialect, self, conn, *args)
  File "/usr/local/lib64/python3.8/site-packages/sqlalchemy/engine/default.py", line 839, in _init_compiled
    param.append(processors[key](compiled_params[key]))
sqlalchemy.exc.StatementError: (builtins.ValueError) could not convert string to float: 'None'
[SQL: INSERT INTO timing (timestamp, dutyfactor, times, acct1, acct2, acct3, acct4) VALUES (?, ?, ?, ?, ?, ?, ?)]
[parameters: [{'acct4': 0, 'acct1': 0, 'times': 0, 'dutyfactor': 'None', 'acct3': 0, 'acct2': 0}]]
Unexpected problem with CA circuit to server "192.168.6.106:5064" was "Connection timed out" - disconnecting
CA.Client.Exception...............................................
    Warning: "Virtual circuit disconnect"
    Context: "192.168.6.106:5064"
    Source File: ../cac.cpp line 1237
    Current Time: Fri Dec 11 2020 22:22:27.084025500
..................................................................
Unexpected problem with CA circuit to server "192.168.6.106:5064" was "Connection timed out" - disconnecting
CA.Client.Exception...............................................
    Warning: "Virtual circuit disconnect"
    Context: "192.168.6.106:5064"
    Source File: ../cac.cpp line 1237
    Current Time: Sat Dec 12 2020 00:37:53.548057741
..................................................................
Unexpected problem with CA circuit to server "192.168.6.106:5064" was "Connection timed out" - disconnecting
CA.Client.Exception...............................................
    Warning: "Virtual circuit disconnect"
    Context: "192.168.6.106:5064"
    Source File: ../cac.cpp line 1237
    Current Time: Sat Dec 12 2020 02:53:20.011080120
..................................................................
Unexpected problem with CA circuit to server "192.168.6.106:5064" was "Connection timed out" - disconnecting
CA.Client.Exception...............................................
    Warning: "Virtual circuit disconnect"
    Context: "192.168.6.106:5064"
    Source File: ../cac.cpp line 1237
    Current Time: Sat Dec 12 2020 05:08:46.475104913
..................................................................
Unexpected problem with CA circuit to server "192.168.6.106:5064" was "Connection timed out" - disconnecting
CA.Client.Exception...............................................
    Warning: "Virtual circuit disconnect"
    Context: "192.168.6.106:5064"
    Source File: ../cac.cpp line 1237
    Current Time: Sat Dec 12 2020 07:24:12.939986862
..................................................................
Unexpected problem with CA circuit to server "192.168.6.106:5064" was "Connection timed out" - disconnecting
CA.Client.Exception...............................................
    Warning: "Virtual circuit disconnect"
    Context: "192.168.6.106:5064"
    Source File: ../cac.cpp line 1237
    Current Time: Sat Dec 12 2020 09:39:39.404014830
..................................................................
CA.Client.Exception...............................................
    Warning: "Virtual circuit disconnect"
    Context: "192.168.6.16:5064"
    Source File: ../cac.cpp line 1237
    Current Time: Sat Dec 12 2020 11:54:39.145953351
..................................................................
Unexpected problem with CA circuit to server "192.168.6.106:5064" was "Connection timed out" - disconnecting
CA.Client.Exception...............................................
    Warning: "Virtual circuit disconnect"
    Context: "192.168.6.106:5064"
    Source File: ../cac.cpp line 1237
    Current Time: Sat Dec 12 2020 11:55:05.867102069
..................................................................
Unexpected problem with CA circuit to server "192.168.6.106:5064" was "Connection timed out" - disconnecting
CA.Client.Exception...............................................
    Warning: "Virtual circuit disconnect"
    Context: "192.168.6.106:5064"
    Source File: ../cac.cpp line 1237
    Current Time: Sat Dec 12 2020 14:10:32.331023747
..................................................................
Unexpected problem with CA circuit to server "192.168.6.106:5064" was "Connection timed out" - disconnecting
CA.Client.Exception...............................................
    Warning: "Virtual circuit disconnect"
    Context: "192.168.6.106:5064"
    Source File: ../cac.cpp line 1237
    Current Time: Sat Dec 12 2020 16:25:58.796065324
..................................................................
CA.Client.Exception...............................................
    Warning: "Virtual circuit unresponsive"
    Context: "192.168.6.16:5064"
    Source File: ../tcpiiu.cpp line 926
    Current Time: Sat Dec 12 2020 17:10:51.177987628
..................................................................
Unexpected problem with CA circuit to server "192.168.2.15:5064" was "Connection reset by peer" - disconnecting
CA.Client.Exception...............................................
    Warning: "Virtual circuit disconnect"
    Context: "192.168.2.15:5064"
    Source File: ../cac.cpp line 1237
    Current Time: Sat Dec 12 2020 17:10:56.203395530
..................................................................
Unexpected problem with CA circuit to server "192.168.6.106:5064" was "Connection timed out" - disconnecting
CA.Client.Exception...............................................
    Warning: "Virtual circuit disconnect"
    Context: "192.168.6.106:5064"
    Source File: ../cac.cpp line 1237
    Current Time: Sat Dec 12 2020 19:25:06.700001411
..................................................................
Unexpected problem with CA circuit to server "192.168.6.106:5064" was "Connection timed out" - disconnecting
CA.Client.Exception...............................................
    Warning: "Virtual circuit disconnect"
    Context: "192.168.6.106:5064"
    Source File: ../cac.cpp line 1237
    Current Time: Sat Dec 12 2020 21:40:33.163094435
..................................................................
Unexpected problem with CA circuit to server "192.168.6.106:5064" was "Connection timed out" - disconnecting
CA.Client.Exception...............................................
    Warning: "Virtual circuit disconnect"
    Context: "192.168.6.106:5064"
    Source File: ../cac.cpp line 1237
    Current Time: Sat Dec 12 2020 23:55:59.627101501
..................................................................
Unexpected problem with CA circuit to server "192.168.6.106:5064" was "Connection timed out" - disconnecting
CA.Client.Exception...............................................
    Warning: "Virtual circuit disconnect"
    Context: "192.168.6.106:5064"
    Source File: ../cac.cpp line 1237
    Current Time: Sun Dec 13 2020 02:11:26.092062351
..................................................................
Unexpected problem with CA circuit to server "192.168.6.106:5064" was "Connection timed out" - disconnecting
CA.Client.Exception...............................................
    Warning: "Virtual circuit disconnect"
    Context: "192.168.6.106:5064"
    Source File: ../cac.cpp line 1237
    Current Time: Sun Dec 13 2020 04:26:52.556010676
..................................................................
Unexpected problem with CA circuit to server "192.168.6.106:5064" was "Connection timed out" - disconnecting
CA.Client.Exception...............................................
    Warning: "Virtual circuit disconnect"
    Context: "192.168.6.106:5064"
    Source File: ../cac.cpp line 1237
    Current Time: Sun Dec 13 2020 06:42:19.020075866
..................................................................
Unexpected problem with CA circuit to server "192.168.6.106:5064" was "Connection timed out" - disconnecting
CA.Client.Exception...............................................
    Warning: "Virtual circuit disconnect"
    Context: "192.168.6.106:5064"
    Source File: ../cac.cpp line 1237
    Current Time: Sun Dec 13 2020 08:57:45.483085376
..................................................................
Unexpected problem with CA circuit to server "192.168.6.106:5064" was "Connection timed out" - disconnecting
CA.Client.Exception...............................................
    Warning: "Virtual circuit disconnect"
    Context: "192.168.6.106:5064"
    Source File: ../cac.cpp line 1237
    Current Time: Sun Dec 13 2020 11:13:11.947122582
..................................................................
Unexpected problem with CA circuit to server "192.168.6.106:5064" was "Connection timed out" - disconnecting
CA.Client.Exception...............................................
    Warning: "Virtual circuit disconnect"
    Context: "192.168.6.106:5064"
    Source File: ../cac.cpp line 1237
    Current Time: Sun Dec 13 2020 13:28:38.412019738
..................................................................
Unexpected problem with CA circuit to server "192.168.6.106:5064" was "Connection timed out" - disconnecting
CA.Client.Exception...............................................
    Warning: "Virtual circuit disconnect"
    Context: "192.168.6.106:5064"
    Source File: ../cac.cpp line 1237
    Current Time: Sun Dec 13 2020 15:44:04.875086592
..................................................................
Unexpected problem with CA circuit to server "192.168.6.106:5064" was "Connection timed out" - disconnecting
CA.Client.Exception...............................................
    Warning: "Virtual circuit disconnect"
    Context: "192.168.6.106:5064"
    Source File: ../cac.cpp line 1237
    Current Time: Sun Dec 13 2020 18:13:43.308078768
..................................................................
Unexpected problem with CA circuit to server "192.168.6.106:5064" was "Connection timed out" - disconnecting
CA.Client.Exception...............................................
    Warning: "Virtual circuit disconnect"
    Context: "192.168.6.106:5064"
    Source File: ../cac.cpp line 1237
    Current Time: Sun Dec 13 2020 21:07:23.531122383
..................................................................
Unexpected problem with CA circuit to server "192.168.6.106:5064" was "Connection timed out" - disconnecting
CA.Client.Exception...............................................
    Warning: "Virtual circuit disconnect"
    Context: "192.168.6.106:5064"
    Source File: ../cac.cpp line 1237
    Current Time: Sun Dec 13 2020 23:41:24.108016916
..................................................................
Unexpected problem with CA circuit to server "192.168.6.106:5064" was "Connection timed out" - disconnecting
CA.Client.Exception...............................................
    Warning: "Virtual circuit disconnect"
    Context: "192.168.6.106:5064"
    Source File: ../cac.cpp line 1237
    Current Time: Mon Dec 14 2020 01:55:45.035007261
..................................................................
Unexpected problem with CA circuit to server "192.168.6.106:5064" was "Connection timed out" - disconnecting
CA.Client.Exception...............................................
    Warning: "Virtual circuit disconnect"
    Context: "192.168.6.106:5064"
    Source File: ../cac.cpp line 1237
    Current Time: Mon Dec 14 2020 04:11:11.499049766
..................................................................
Unexpected problem with CA circuit to server "192.168.6.106:5064" was "Connection timed out" - disconnecting
CA.Client.Exception...............................................
    Warning: "Virtual circuit disconnect"
    Context: "192.168.6.106:5064"
    Source File: ../cac.cpp line 1237
    Current Time: Mon Dec 14 2020 06:26:37.963059909
..................................................................
Unexpected problem with CA circuit to server "192.168.6.106:5064" was "Connection timed out" - disconnecting
CA.Client.Exception...............................................
    Warning: "Virtual circuit disconnect"
    Context: "192.168.6.106:5064"
    Source File: ../cac.cpp line 1237
    Current Time: Mon Dec 14 2020 08:42:04.428057155
..................................................................
Unexpected problem with CA circuit to server "192.168.6.106:5064" was "Connection timed out" - disconnecting
CA.Client.Exception...............................................
    Warning: "Virtual circuit disconnect"
    Context: "192.168.6.106:5064"
    Source File: ../cac.cpp line 1237
    Current Time: Mon Dec 14 2020 10:57:30.892071186
..................................................................
Unexpected problem with CA circuit to server "192.168.6.106:5064" was "Connection timed out" - disconnecting
CA.Client.Exception...............................................
    Warning: "Virtual circuit disconnect"
    Context: "192.168.6.106:5064"
    Source File: ../cac.cpp line 1237
    Current Time: Mon Dec 14 2020 13:12:57.356089122
..................................................................
Unexpected problem with CA circuit to server "192.168.6.106:5064" was "Connection timed out" - disconnecting
CA.Client.Exception...............................................
    Warning: "Virtual circuit disconnect"
    Context: "192.168.6.106:5064"
    Source File: ../cac.cpp line 1237
    Current Time: Mon Dec 14 2020 16:00:04.363065071
..................................................................
Unexpected problem with CA circuit to server "192.168.6.106:5064" was "Connection timed out" - disconnecting
CA.Client.Exception...............................................
    Warning: "Virtual circuit disconnect"
    Context: "192.168.6.106:5064"
    Source File: ../cac.cpp line 1237
    Current Time: Mon Dec 14 2020 18:25:53.419098236
..................................................................

worker: Warm shutdown (MainProcess)
Started at 2020-12-14 20:58:49
 
 -------------- celery@localhost.localdomain v5.0.2 (singularity)
--- ***** ----- 
-- ******* ---- Linux-5.8.11-200.fc32.x86_64-x86_64-with-glibc2.2.5 2020-12-14 20:58:50
- *** --- * --- 
- ** ---------- [config]
- ** ---------- .> app:         backend.main:0x7f88bb82e850
- ** ---------- .> transport:   redis://localhost:6379//
- ** ---------- .> results:     redis://localhost:6379/
- *** --- * --- .> concurrency: 8 (prefork)
-- ******* ---- .> task events: OFF (enable -E to monitor tasks in this worker)
--- ***** ----- 
 -------------- [queues]
                .> celery           exchange=celery(direct) key=celery
                

[tasks]
  . backend.main.tasks.accumulate_time

[2020-12-14 20:58:50,447: INFO/MainProcess] Connected to redis://localhost:6379//
[2020-12-14 20:58:50,453: INFO/MainProcess] mingle: searching for neighbors
[2020-12-14 20:58:51,468: INFO/MainProcess] mingle: all alone
[2020-12-14 20:58:51,494: INFO/MainProcess] celery@localhost.localdomain ready.
[2020-12-14 21:38:55,699: INFO/MainProcess] Received task: backend.main.tasks.accumulate_time[afad3849-25ec-4b31-ad63-e737e6e96413]  
Warning: Duplicate EPICS CA Address list entry "192.168.40.4:5064" discarded
[2020-12-14 21:38:55,738: WARNING/ForkPoolWorker-7] 0.002
Unexpected problem with CA circuit to server "192.168.6.106:5064" was "Connection timed out" - disconnecting
CA.Client.Exception...............................................
    Warning: "Virtual circuit disconnect"
    Context: "192.168.6.106:5064"
    Source File: ../cac.cpp line 1237
    Current Time: Tue Dec 15 2020 00:34:31.819803313
..................................................................
Unexpected problem with CA circuit to server "192.168.6.106:5064" was "Connection timed out" - disconnecting
CA.Client.Exception...............................................
    Warning: "Virtual circuit disconnect"
    Context: "192.168.6.106:5064"
    Source File: ../cac.cpp line 1237
    Current Time: Tue Dec 15 2020 03:46:46.154970919
..................................................................
Unexpected problem with CA circuit to server "192.168.6.106:5064" was "Connection timed out" - disconnecting
CA.Client.Exception...............................................
    Warning: "Virtual circuit disconnect"
    Context: "192.168.6.106:5064"
    Source File: ../cac.cpp line 1237
    Current Time: Tue Dec 15 2020 06:02:12.619059162
..................................................................
Unexpected problem with CA circuit to server "192.168.6.106:5064" was "Connection timed out" - disconnecting
CA.Client.Exception...............................................
    Warning: "Virtual circuit disconnect"
    Context: "192.168.6.106:5064"
    Source File: ../cac.cpp line 1237
    Current Time: Tue Dec 15 2020 08:17:39.083085750
..................................................................
[2020-12-15 08:30:00,955: ERROR/ForkPoolWorker-7] Task backend.main.tasks.accumulate_time[afad3849-25ec-4b31-ad63-e737e6e96413] raised unexpected: StatementError("(builtins.ValueError) could not convert string to float: 'None'")
Traceback (most recent call last):
  File "/usr/local/lib64/python3.8/site-packages/sqlalchemy/engine/base.py", line 1204, in _execute_context
    context = constructor(dialect, self, conn, *args)
  File "/usr/local/lib64/python3.8/site-packages/sqlalchemy/engine/default.py", line 839, in _init_compiled
    param.append(processors[key](compiled_params[key]))
ValueError: could not convert string to float: 'None'

The above exception was the direct cause of the following exception:

Traceback (most recent call last):
  File "/usr/local/lib/python3.8/site-packages/celery/app/trace.py", line 409, in trace_task
    R = retval = fun(*args, **kwargs)
  File "/home/linac/commissioning/lattice-setting/backend/main/celery_utils.py", line 9, in __call__
    call_res = TaskBase.__call__(self, *args, **kwargs)
  File "/usr/local/lib/python3.8/site-packages/celery/app/trace.py", line 701, in __protected_call__
    return self.run(*args, **kwargs)
  File "/home/linac/commissioning/lattice-setting/backend/main/tasks.py", line 164, in accumulate_time
    prev_time, timing_dict = timing_add_needed(current_time, prev_time,
  File "/home/linac/commissioning/lattice-setting/backend/main/tasks.py", line 101, in timing_add_needed
    save_timing(timing_dict)
  File "/home/linac/commissioning/lattice-setting/backend/main/tasks.py", line 37, in save_timing
    db.session.commit()
  File "/usr/local/lib64/python3.8/site-packages/sqlalchemy/orm/scoping.py", line 163, in do
    return getattr(self.registry(), name)(*args, **kwargs)
  File "/usr/local/lib64/python3.8/site-packages/sqlalchemy/orm/session.py", line 1042, in commit
    self.transaction.commit()
  File "/usr/local/lib64/python3.8/site-packages/sqlalchemy/orm/session.py", line 504, in commit
    self._prepare_impl()
  File "/usr/local/lib64/python3.8/site-packages/sqlalchemy/orm/session.py", line 483, in _prepare_impl
    self.session.flush()
  File "/usr/local/lib64/python3.8/site-packages/sqlalchemy/orm/session.py", line 2536, in flush
    self._flush(objects)
  File "/usr/local/lib64/python3.8/site-packages/sqlalchemy/orm/session.py", line 2678, in _flush
    transaction.rollback(_capture_exception=True)
  File "/usr/local/lib64/python3.8/site-packages/sqlalchemy/util/langhelpers.py", line 68, in __exit__
    compat.raise_(
  File "/usr/local/lib64/python3.8/site-packages/sqlalchemy/util/compat.py", line 182, in raise_
    raise exception
  File "/usr/local/lib64/python3.8/site-packages/sqlalchemy/orm/session.py", line 2638, in _flush
    flush_context.execute()
  File "/usr/local/lib64/python3.8/site-packages/sqlalchemy/orm/unitofwork.py", line 422, in execute
    rec.execute(self)
  File "/usr/local/lib64/python3.8/site-packages/sqlalchemy/orm/unitofwork.py", line 586, in execute
    persistence.save_obj(
  File "/usr/local/lib64/python3.8/site-packages/sqlalchemy/orm/persistence.py", line 239, in save_obj
    _emit_insert_statements(
  File "/usr/local/lib64/python3.8/site-packages/sqlalchemy/orm/persistence.py", line 1135, in _emit_insert_statements
    result = cached_connections[connection].execute(
  File "/usr/local/lib64/python3.8/site-packages/sqlalchemy/engine/base.py", line 1011, in execute
    return meth(self, multiparams, params)
  File "/usr/local/lib64/python3.8/site-packages/sqlalchemy/sql/elements.py", line 298, in _execute_on_connection
    return connection._execute_clauseelement(self, multiparams, params)
  File "/usr/local/lib64/python3.8/site-packages/sqlalchemy/engine/base.py", line 1124, in _execute_clauseelement
    ret = self._execute_context(
  File "/usr/local/lib64/python3.8/site-packages/sqlalchemy/engine/base.py", line 1206, in _execute_context
    self._handle_dbapi_exception(
  File "/usr/local/lib64/python3.8/site-packages/sqlalchemy/engine/base.py", line 1510, in _handle_dbapi_exception
    util.raise_(
  File "/usr/local/lib64/python3.8/site-packages/sqlalchemy/util/compat.py", line 182, in raise_
    raise exception
  File "/usr/local/lib64/python3.8/site-packages/sqlalchemy/engine/base.py", line 1204, in _execute_context
    context = constructor(dialect, self, conn, *args)
  File "/usr/local/lib64/python3.8/site-packages/sqlalchemy/engine/default.py", line 839, in _init_compiled
    param.append(processors[key](compiled_params[key]))
sqlalchemy.exc.StatementError: (builtins.ValueError) could not convert string to float: 'None'
[SQL: INSERT INTO timing (timestamp, dutyfactor, times, acct1, acct2, acct3, acct4) VALUES (?, ?, ?, ?, ?, ?, ?)]
[parameters: [{'acct1': 4.404108095169067, 'acct2': 4.2189257621765135, 'acct3': 2.989817618392408, 'acct4': -0.0020377606619149447, 'times': 25.49513006210327, 'dutyfactor': 'None'}]]
Unexpected problem with CA circuit to server "192.168.6.106:5064" was "Connection timed out" - disconnecting
CA.Client.Exception...............................................
    Warning: "Virtual circuit disconnect"
    Context: "192.168.6.106:5064"
    Source File: ../cac.cpp line 1237
    Current Time: Tue Dec 15 2020 10:33:05.547071748
..................................................................
Unexpected problem with CA circuit to server "192.168.6.106:5064" was "Connection timed out" - disconnecting
CA.Client.Exception...............................................
    Warning: "Virtual circuit disconnect"
    Context: "192.168.6.106:5064"
    Source File: ../cac.cpp line 1237
    Current Time: Tue Dec 15 2020 12:48:32.011046084
..................................................................
Unexpected problem with CA circuit to server "192.168.6.106:5064" was "Connection timed out" - disconnecting
CA.Client.Exception...............................................
    Warning: "Virtual circuit disconnect"
    Context: "192.168.6.106:5064"
    Source File: ../cac.cpp line 1237
    Current Time: Tue Dec 15 2020 15:03:58.476125928
..................................................................
Unexpected problem with CA circuit to server "192.168.6.106:5064" was "Connection timed out" - disconnecting
CA.Client.Exception...............................................
    Warning: "Virtual circuit disconnect"
    Context: "192.168.6.106:5064"
    Source File: ../cac.cpp line 1237
    Current Time: Tue Dec 15 2020 17:19:24.939912229
..................................................................
Unexpected problem with CA circuit to server "192.168.6.106:5064" was "Connection timed out" - disconnecting
CA.Client.Exception...............................................
    Warning: "Virtual circuit disconnect"
    Context: "192.168.6.106:5064"
    Source File: ../cac.cpp line 1237
    Current Time: Tue Dec 15 2020 19:34:51.403984600
..................................................................
Unexpected problem with CA circuit to server "192.168.6.106:5064" was "Connection timed out" - disconnecting
CA.Client.Exception...............................................
    Warning: "Virtual circuit disconnect"
    Context: "192.168.6.106:5064"
    Source File: ../cac.cpp line 1237
    Current Time: Tue Dec 15 2020 21:50:17.866991444
..................................................................
Unexpected problem with CA circuit to server "192.168.6.106:5064" was "Connection timed out" - disconnecting
CA.Client.Exception...............................................
    Warning: "Virtual circuit disconnect"
    Context: "192.168.6.106:5064"
    Source File: ../cac.cpp line 1237
    Current Time: Wed Dec 16 2020 00:05:44.332099856
..................................................................
Unexpected problem with CA circuit to server "192.168.6.106:5064" was "Connection timed out" - disconnecting
CA.Client.Exception...............................................
    Warning: "Virtual circuit disconnect"
    Context: "192.168.6.106:5064"
    Source File: ../cac.cpp line 1237
    Current Time: Wed Dec 16 2020 02:21:10.796090723
..................................................................
Unexpected problem with CA circuit to server "192.168.6.106:5064" was "Connection timed out" - disconnecting
CA.Client.Exception...............................................
    Warning: "Virtual circuit disconnect"
    Context: "192.168.6.106:5064"
    Source File: ../cac.cpp line 1237
    Current Time: Wed Dec 16 2020 04:36:37.260069548
..................................................................
Unexpected problem with CA circuit to server "192.168.6.106:5064" was "Connection timed out" - disconnecting
CA.Client.Exception...............................................
    Warning: "Virtual circuit disconnect"
    Context: "192.168.6.106:5064"
    Source File: ../cac.cpp line 1237
    Current Time: Wed Dec 16 2020 06:52:03.723086348
..................................................................
Unexpected problem with CA circuit to server "192.168.6.106:5064" was "Connection timed out" - disconnecting
CA.Client.Exception...............................................
    Warning: "Virtual circuit disconnect"
    Context: "192.168.6.106:5064"
    Source File: ../cac.cpp line 1237
    Current Time: Wed Dec 16 2020 09:07:30.187952476
..................................................................
Unexpected problem with CA circuit to server "192.168.6.106:5064" was "Connection timed out" - disconnecting
CA.Client.Exception...............................................
    Warning: "Virtual circuit disconnect"
    Context: "192.168.6.106:5064"
    Source File: ../cac.cpp line 1237
    Current Time: Wed Dec 16 2020 11:22:56.651999045
..................................................................
Unexpected problem with CA circuit to server "192.168.6.106:5064" was "Connection timed out" - disconnecting
CA.Client.Exception...............................................
    Warning: "Virtual circuit disconnect"
    Context: "192.168.6.106:5064"
    Source File: ../cac.cpp line 1237
    Current Time: Wed Dec 16 2020 13:38:23.115061849
..................................................................
Unexpected problem with CA circuit to server "192.168.6.106:5064" was "Connection timed out" - disconnecting
CA.Client.Exception...............................................
    Warning: "Virtual circuit disconnect"
    Context: "192.168.6.106:5064"
    Source File: ../cac.cpp line 1237
    Current Time: Wed Dec 16 2020 15:53:49.579035379
..................................................................
Unexpected problem with CA circuit to server "192.168.6.106:5064" was "Connection timed out" - disconnecting
CA.Client.Exception...............................................
    Warning: "Virtual circuit disconnect"
    Context: "192.168.6.106:5064"
    Source File: ../cac.cpp line 1237
    Current Time: Wed Dec 16 2020 20:15:58.219076621
..................................................................
Unexpected problem with CA circuit to server "192.168.6.106:5064" was "Connection timed out" - disconnecting
CA.Client.Exception...............................................
    Warning: "Virtual circuit disconnect"
    Context: "192.168.6.106:5064"
    Source File: ../cac.cpp line 1237
    Current Time: Wed Dec 16 2020 22:31:24.682996517
..................................................................
Unexpected problem with CA circuit to server "192.168.6.106:5064" was "Connection timed out" - disconnecting
CA.Client.Exception...............................................
    Warning: "Virtual circuit disconnect"
    Context: "192.168.6.106:5064"
    Source File: ../cac.cpp line 1237
    Current Time: Thu Dec 17 2020 00:46:51.147045312
..................................................................
Unexpected problem with CA circuit to server "192.168.6.106:5064" was "Connection timed out" - disconnecting
CA.Client.Exception...............................................
    Warning: "Virtual circuit disconnect"
    Context: "192.168.6.106:5064"
    Source File: ../cac.cpp line 1237
    Current Time: Thu Dec 17 2020 03:02:17.612101944
..................................................................
Unexpected problem with CA circuit to server "192.168.6.106:5064" was "Connection timed out" - disconnecting
CA.Client.Exception...............................................
    Warning: "Virtual circuit disconnect"
    Context: "192.168.6.106:5064"
    Source File: ../cac.cpp line 1237
    Current Time: Thu Dec 17 2020 05:17:44.075073257
..................................................................
Unexpected problem with CA circuit to server "192.168.6.106:5064" was "Connection timed out" - disconnecting
CA.Client.Exception...............................................
    Warning: "Virtual circuit disconnect"
    Context: "192.168.6.106:5064"
    Source File: ../cac.cpp line 1237
    Current Time: Thu Dec 17 2020 07:33:10.539966444
..................................................................
CA.Client.Exception...............................................
    Warning: "Virtual circuit unresponsive"
    Context: "192.168.6.106:5064"
    Source File: ../tcpiiu.cpp line 926
    Current Time: Thu Dec 17 2020 09:03:00.668289497
..................................................................
Unexpected problem with CA circuit to server "192.168.6.106:5064" was "Connection timed out" - disconnecting
CA.Client.Exception...............................................
    Warning: "Virtual circuit disconnect"
    Context: "192.168.6.106:5064"
    Source File: ../cac.cpp line 1237
    Current Time: Thu Dec 17 2020 09:18:47.051048415
..................................................................
Unexpected problem with CA circuit to server "192.168.6.106:5064" was "Connection timed out" - disconnecting
CA.Client.Exception...............................................
    Warning: "Virtual circuit disconnect"
    Context: "192.168.6.106:5064"
    Source File: ../cac.cpp line 1237
    Current Time: Thu Dec 17 2020 11:33:28.459001610
..................................................................
Unexpected problem with CA circuit to server "192.168.2.15:5064" was "Connection reset by peer" - disconnecting
CA.Client.Exception...............................................
    Warning: "Virtual circuit disconnect"
    Context: "192.168.2.15:5064"
    Source File: ../cac.cpp line 1237
    Current Time: Thu Dec 17 2020 11:40:35.469273167
..................................................................
CA.Client.Exception...............................................
    Warning: "Virtual circuit unresponsive"
    Context: "192.168.6.106:5064"
    Source File: ../tcpiiu.cpp line 926
    Current Time: Thu Dec 17 2020 11:40:35.545435971
..................................................................
CA.Client.Exception...............................................
    Warning: "Virtual circuit unresponsive"
    Context: "192.168.6.16:5064"
    Source File: ../tcpiiu.cpp line 926
    Current Time: Thu Dec 17 2020 11:40:38.935887769
..................................................................
CA.Client.Exception...............................................
    Warning: "Virtual circuit unresponsive"
    Context: "192.168.6.106:5064"
    Source File: ../tcpiiu.cpp line 926
    Current Time: Thu Dec 17 2020 12:47:03.569279776
..................................................................
Unexpected problem with CA circuit to server "192.168.6.106:5064" was "Connection timed out" - disconnecting
CA.Client.Exception...............................................
    Warning: "Virtual circuit disconnect"
    Context: "192.168.6.106:5064"
    Source File: ../cac.cpp line 1237
    Current Time: Thu Dec 17 2020 13:02:50.123042659
..................................................................
Unexpected problem with CA circuit to server "192.168.6.106:5064" was "Connection reset by peer" - disconnecting
CA.Client.Exception...............................................
    Warning: "Virtual circuit disconnect"
    Context: "192.168.6.106:5064"
    Source File: ../cac.cpp line 1237
    Current Time: Thu Dec 17 2020 14:09:40.712523464
..................................................................
Unexpected problem with CA circuit to server "192.168.6.106:5064" was "Connection timed out" - disconnecting
CA.Client.Exception...............................................
    Warning: "Virtual circuit disconnect"
    Context: "192.168.6.106:5064"
    Source File: ../cac.cpp line 1237
    Current Time: Thu Dec 17 2020 16:27:50.411102458
..................................................................
Unexpected problem with CA circuit to server "192.168.6.106:5064" was "Connection timed out" - disconnecting
CA.Client.Exception...............................................
    Warning: "Virtual circuit disconnect"
    Context: "192.168.6.106:5064"
    Source File: ../cac.cpp line 1237
    Current Time: Thu Dec 17 2020 19:34:04.299085977
..................................................................
Unexpected problem with CA circuit to server "192.168.6.106:5064" was "Connection timed out" - disconnecting
CA.Client.Exception...............................................
    Warning: "Virtual circuit disconnect"
    Context: "192.168.6.106:5064"
    Source File: ../cac.cpp line 1237
    Current Time: Thu Dec 17 2020 21:49:30.762980107
..................................................................
Unexpected problem with CA circuit to server "192.168.6.106:5064" was "Connection timed out" - disconnecting
CA.Client.Exception...............................................
    Warning: "Virtual circuit disconnect"
    Context: "192.168.6.106:5064"
    Source File: ../cac.cpp line 1237
    Current Time: Fri Dec 18 2020 00:04:57.228096418
..................................................................
Unexpected problem with CA circuit to server "192.168.6.106:5064" was "Connection timed out" - disconnecting
CA.Client.Exception...............................................
    Warning: "Virtual circuit disconnect"
    Context: "192.168.6.106:5064"
    Source File: ../cac.cpp line 1237
    Current Time: Fri Dec 18 2020 02:20:23.690981099
..................................................................
Unexpected problem with CA circuit to server "192.168.6.106:5064" was "Connection timed out" - disconnecting
CA.Client.Exception...............................................
    Warning: "Virtual circuit disconnect"
    Context: "192.168.6.106:5064"
    Source File: ../cac.cpp line 1237
    Current Time: Fri Dec 18 2020 04:35:50.155124941
..................................................................
Unexpected problem with CA circuit to server "192.168.6.106:5064" was "Connection timed out" - disconnecting
CA.Client.Exception...............................................
    Warning: "Virtual circuit disconnect"
    Context: "192.168.6.106:5064"
    Source File: ../cac.cpp line 1237
    Current Time: Fri Dec 18 2020 06:51:16.620004217
..................................................................
Unexpected problem with CA circuit to server "192.168.6.106:5064" was "Connection timed out" - disconnecting
CA.Client.Exception...............................................
    Warning: "Virtual circuit disconnect"
    Context: "192.168.6.106:5064"
    Source File: ../cac.cpp line 1237
    Current Time: Fri Dec 18 2020 09:06:43.083089581
..................................................................
Unexpected problem with CA circuit to server "192.168.6.106:5064" was "Connection timed out" - disconnecting
CA.Client.Exception...............................................
    Warning: "Virtual circuit disconnect"
    Context: "192.168.6.106:5064"
    Source File: ../cac.cpp line 1237
    Current Time: Fri Dec 18 2020 11:22:09.548026210
..................................................................
Unexpected problem with CA circuit to server "192.168.6.106:5064" was "Connection timed out" - disconnecting
CA.Client.Exception...............................................
    Warning: "Virtual circuit disconnect"
    Context: "192.168.6.106:5064"
    Source File: ../cac.cpp line 1237
    Current Time: Fri Dec 18 2020 13:37:36.011057286
..................................................................
Unexpected problem with CA circuit to server "192.168.6.106:5064" was "Connection timed out" - disconnecting
CA.Client.Exception...............................................
    Warning: "Virtual circuit disconnect"
    Context: "192.168.6.106:5064"
    Source File: ../cac.cpp line 1237
    Current Time: Fri Dec 18 2020 15:53:02.476049070
..................................................................
CA.Client.Exception...............................................
    Warning: "Virtual circuit unresponsive"
    Context: "192.168.6.106:5064"
    Source File: ../tcpiiu.cpp line 926
    Current Time: Fri Dec 18 2020 18:09:08.376150909
..................................................................
Unexpected problem with CA circuit to server "192.168.6.106:5064" was "Connection timed out" - disconnecting
CA.Client.Exception...............................................
    Warning: "Virtual circuit disconnect"
    Context: "192.168.6.106:5064"
    Source File: ../cac.cpp line 1237
    Current Time: Fri Dec 18 2020 18:24:51.979053209
..................................................................
Unexpected problem with CA circuit to server "192.168.6.106:5064" was "Connection timed out" - disconnecting
CA.Client.Exception...............................................
    Warning: "Virtual circuit disconnect"
    Context: "192.168.6.106:5064"
    Source File: ../cac.cpp line 1237
    Current Time: Fri Dec 18 2020 20:37:01.835044340
..................................................................
Unexpected problem with CA circuit to server "192.168.6.106:5064" was "Connection timed out" - disconnecting
CA.Client.Exception...............................................
    Warning: "Virtual circuit disconnect"
    Context: "192.168.6.106:5064"
    Source File: ../cac.cpp line 1237
    Current Time: Fri Dec 18 2020 22:52:28.298976458
..................................................................
Unexpected problem with CA circuit to server "192.168.6.106:5064" was "Connection timed out" - disconnecting
CA.Client.Exception...............................................
    Warning: "Virtual circuit disconnect"
    Context: "192.168.6.106:5064"
    Source File: ../cac.cpp line 1237
    Current Time: Sat Dec 19 2020 01:07:54.764095301
..................................................................
Unexpected problem with CA circuit to server "192.168.6.106:5064" was "Connection timed out" - disconnecting
CA.Client.Exception...............................................
    Warning: "Virtual circuit disconnect"
    Context: "192.168.6.106:5064"
    Source File: ../cac.cpp line 1237
    Current Time: Sat Dec 19 2020 03:23:21.227062494
..................................................................
Unexpected problem with CA circuit to server "192.168.6.106:5064" was "Connection timed out" - disconnecting
CA.Client.Exception...............................................
    Warning: "Virtual circuit disconnect"
    Context: "192.168.6.106:5064"
    Source File: ../cac.cpp line 1237
    Current Time: Sat Dec 19 2020 05:38:47.691075034
..................................................................
Unexpected problem with CA circuit to server "192.168.6.106:5064" was "Connection timed out" - disconnecting
CA.Client.Exception...............................................
    Warning: "Virtual circuit disconnect"
    Context: "192.168.6.106:5064"
    Source File: ../cac.cpp line 1237
    Current Time: Sat Dec 19 2020 07:54:14.155061809
..................................................................
Unexpected problem with CA circuit to server "192.168.6.106:5064" was "Connection timed out" - disconnecting
CA.Client.Exception...............................................
    Warning: "Virtual circuit disconnect"
    Context: "192.168.6.106:5064"
    Source File: ../cac.cpp line 1237
    Current Time: Sat Dec 19 2020 10:09:40.620040852
..................................................................
Unexpected problem with CA circuit to server "192.168.6.106:5064" was "Connection timed out" - disconnecting
CA.Client.Exception...............................................
    Warning: "Virtual circuit disconnect"
    Context: "192.168.6.106:5064"
    Source File: ../cac.cpp line 1237
    Current Time: Sat Dec 19 2020 12:25:07.082991465
..................................................................
Unexpected problem with CA circuit to server "192.168.6.106:5064" was "Connection timed out" - disconnecting
CA.Client.Exception...............................................
    Warning: "Virtual circuit disconnect"
    Context: "192.168.6.106:5064"
    Source File: ../cac.cpp line 1237
    Current Time: Sat Dec 19 2020 14:40:33.546940939
..................................................................
Unexpected problem with CA circuit to server "192.168.6.106:5064" was "Connection timed out" - disconnecting
CA.Client.Exception...............................................
    Warning: "Virtual circuit disconnect"
    Context: "192.168.6.106:5064"
    Source File: ../cac.cpp line 1237
    Current Time: Sat Dec 19 2020 16:56:00.012112095
..................................................................
Unexpected problem with CA circuit to server "192.168.6.106:5064" was "Connection timed out" - disconnecting
CA.Client.Exception...............................................
    Warning: "Virtual circuit disconnect"
    Context: "192.168.6.106:5064"
    Source File: ../cac.cpp line 1237
    Current Time: Sat Dec 19 2020 19:11:26.475101901
..................................................................
Unexpected problem with CA circuit to server "192.168.6.106:5064" was "Connection timed out" - disconnecting
CA.Client.Exception...............................................
    Warning: "Virtual circuit disconnect"
    Context: "192.168.6.106:5064"
    Source File: ../cac.cpp line 1237
    Current Time: Sat Dec 19 2020 21:26:52.938988390
..................................................................
Unexpected problem with CA circuit to server "192.168.6.106:5064" was "Connection timed out" - disconnecting
CA.Client.Exception...............................................
    Warning: "Virtual circuit disconnect"
    Context: "192.168.6.106:5064"
    Source File: ../cac.cpp line 1237
    Current Time: Sat Dec 19 2020 23:42:19.403068774
..................................................................
Unexpected problem with CA circuit to server "192.168.6.106:5064" was "Connection timed out" - disconnecting
CA.Client.Exception...............................................
    Warning: "Virtual circuit disconnect"
    Context: "192.168.6.106:5064"
    Source File: ../cac.cpp line 1237
    Current Time: Sun Dec 20 2020 01:57:45.867081245
..................................................................
Unexpected problem with CA circuit to server "192.168.6.106:5064" was "Connection timed out" - disconnecting
CA.Client.Exception...............................................
    Warning: "Virtual circuit disconnect"
    Context: "192.168.6.106:5064"
    Source File: ../cac.cpp line 1237
    Current Time: Sun Dec 20 2020 04:13:12.331066489
..................................................................
Unexpected problem with CA circuit to server "192.168.6.106:5064" was "Connection timed out" - disconnecting
CA.Client.Exception...............................................
    Warning: "Virtual circuit disconnect"
    Context: "192.168.6.106:5064"
    Source File: ../cac.cpp line 1237
    Current Time: Sun Dec 20 2020 06:28:38.795001269
..................................................................
Unexpected problem with CA circuit to server "192.168.6.106:5064" was "Connection timed out" - disconnecting
CA.Client.Exception...............................................
    Warning: "Virtual circuit disconnect"
    Context: "192.168.6.106:5064"
    Source File: ../cac.cpp line 1237
    Current Time: Sun Dec 20 2020 08:44:05.258996529
..................................................................

worker: Warm shutdown (MainProcess)
Started at 2020-12-20 08:49:25
 
 -------------- celery@localhost.localdomain v5.0.2 (singularity)
--- ***** ----- 
-- ******* ---- Linux-5.8.11-200.fc32.x86_64-x86_64-with-glibc2.2.5 2020-12-20 08:49:25
- *** --- * --- 
- ** ---------- [config]
- ** ---------- .> app:         backend.main:0x7f12ac6b7850
- ** ---------- .> transport:   redis://localhost:6379//
- ** ---------- .> results:     redis://localhost:6379/
- *** --- * --- .> concurrency: 8 (prefork)
-- ******* ---- .> task events: OFF (enable -E to monitor tasks in this worker)
--- ***** ----- 
 -------------- [queues]
                .> celery           exchange=celery(direct) key=celery
                

[tasks]
  . backend.main.tasks.accumulate_time

[2020-12-20 08:49:25,942: INFO/MainProcess] Connected to redis://localhost:6379//
[2020-12-20 08:49:25,948: INFO/MainProcess] mingle: searching for neighbors
[2020-12-20 08:49:26,962: INFO/MainProcess] mingle: all alone
[2020-12-20 08:49:26,990: INFO/MainProcess] celery@localhost.localdomain ready.
[2020-12-20 08:49:47,659: INFO/MainProcess] Received task: backend.main.tasks.accumulate_time[7896dd2b-064a-4fea-873d-3847a91a931c]  
Warning: Duplicate EPICS CA Address list entry "192.168.40.4:5064" discarded
[2020-12-20 08:49:47,704: WARNING/ForkPoolWorker-7] 0.0009993846153846153
[2020-12-20 08:54:45,290: INFO/ForkPoolWorker-7] Task backend.main.tasks.accumulate_time[7896dd2b-064a-4fea-873d-3847a91a931c] succeeded in 297.62837005907204s: None

worker: Warm shutdown (MainProcess)
Started at 2020-12-20 08:56:48
 
 -------------- celery@localhost.localdomain v5.0.2 (singularity)
--- ***** ----- 
-- ******* ---- Linux-5.8.11-200.fc32.x86_64-x86_64-with-glibc2.2.5 2020-12-20 08:56:49
- *** --- * --- 
- ** ---------- [config]
- ** ---------- .> app:         backend.main:0x7f46f713a7f0
- ** ---------- .> transport:   redis://localhost:6379//
- ** ---------- .> results:     redis://localhost:6379/
- *** --- * --- .> concurrency: 8 (prefork)
-- ******* ---- .> task events: OFF (enable -E to monitor tasks in this worker)
--- ***** ----- 
 -------------- [queues]
                .> celery           exchange=celery(direct) key=celery
                

[tasks]
  . backend.main.tasks.accumulate_time

[2020-12-20 08:56:49,830: INFO/MainProcess] Connected to redis://localhost:6379//
[2020-12-20 08:56:49,837: INFO/MainProcess] mingle: searching for neighbors
[2020-12-20 08:56:50,852: INFO/MainProcess] mingle: all alone
[2020-12-20 08:56:50,876: INFO/MainProcess] celery@localhost.localdomain ready.
[2020-12-20 08:56:56,106: INFO/MainProcess] Received task: backend.main.tasks.accumulate_time[7cf401a2-7d7a-4d6e-b552-d31aaef361d9]  
Warning: Duplicate EPICS CA Address list entry "192.168.40.4:5064" discarded
[2020-12-20 08:56:56,151: WARNING/ForkPoolWorker-7] 0.0009993846153846153

worker: Warm shutdown (MainProcess)
[2020-12-20 08:58:38,757: ERROR/MainProcess] Process 'ForkPoolWorker-8' pid:65093 exited with 'signal 15 (SIGTERM)'
[2020-12-20 08:58:38,767: ERROR/MainProcess] Process 'ForkPoolWorker-7' pid:65092 exited with 'signal 15 (SIGTERM)'
[2020-12-20 08:58:38,778: ERROR/MainProcess] Process 'ForkPoolWorker-3' pid:65088 exited with 'signal 15 (SIGTERM)'
[2020-12-20 08:58:38,788: ERROR/MainProcess] Process 'ForkPoolWorker-2' pid:65087 exited with 'signal 15 (SIGTERM)'
[2020-12-20 08:58:38,799: ERROR/MainProcess] Process 'ForkPoolWorker-1' pid:65086 exited with 'signal 15 (SIGTERM)'
[2020-12-20 08:58:38,821: ERROR/MainProcess] Task handler raised error: WorkerLostError('Worker exited prematurely: signal 15 (SIGTERM).')
Traceback (most recent call last):
  File "/usr/local/lib/python3.8/site-packages/celery/worker/worker.py", line 203, in start
    self.blueprint.start(self)
  File "/usr/local/lib/python3.8/site-packages/celery/bootsteps.py", line 116, in start
    step.start(parent)
  File "/usr/local/lib/python3.8/site-packages/celery/bootsteps.py", line 365, in start
    return self.obj.start()
  File "/usr/local/lib/python3.8/site-packages/celery/worker/consumer/consumer.py", line 311, in start
    blueprint.start(self)
  File "/usr/local/lib/python3.8/site-packages/celery/bootsteps.py", line 116, in start
    step.start(parent)
  File "/usr/local/lib/python3.8/site-packages/celery/worker/consumer/consumer.py", line 592, in start
    c.loop(*c.loop_args())
  File "/usr/local/lib/python3.8/site-packages/celery/worker/loops.py", line 72, in asynloop
    state.maybe_shutdown()
  File "/usr/local/lib/python3.8/site-packages/celery/worker/state.py", line 77, in maybe_shutdown
    raise WorkerShutdown(should_stop)
celery.exceptions.WorkerShutdown: 0

During handling of the above exception, another exception occurred:

Traceback (most recent call last):
  File "/usr/local/lib/python3.8/site-packages/billiard/pool.py", line 1265, in mark_as_worker_lost
    raise WorkerLostError(
billiard.exceptions.WorkerLostError: Worker exited prematurely: signal 15 (SIGTERM).
Started at 2020-12-20 09:00:12
 
 -------------- celery@localhost.localdomain v5.0.2 (singularity)
--- ***** ----- 
-- ******* ---- Linux-5.8.11-200.fc32.x86_64-x86_64-with-glibc2.2.5 2020-12-20 09:00:12
- *** --- * --- 
- ** ---------- [config]
- ** ---------- .> app:         backend.main:0x7fa95c5927f0
- ** ---------- .> transport:   redis://localhost:6379//
- ** ---------- .> results:     redis://localhost:6379/
- *** --- * --- .> concurrency: 8 (prefork)
-- ******* ---- .> task events: OFF (enable -E to monitor tasks in this worker)
--- ***** ----- 
 -------------- [queues]
                .> celery           exchange=celery(direct) key=celery
                

[tasks]
  . backend.main.tasks.accumulate_time

[2020-12-20 09:00:13,214: INFO/MainProcess] Connected to redis://localhost:6379//
[2020-12-20 09:00:13,220: INFO/MainProcess] mingle: searching for neighbors
[2020-12-20 09:00:14,235: INFO/MainProcess] mingle: all alone
[2020-12-20 09:00:14,260: INFO/MainProcess] celery@localhost.localdomain ready.
[2020-12-20 09:00:28,340: INFO/MainProcess] Received task: backend.main.tasks.accumulate_time[3cda0f5a-b1a3-4de8-b86b-4ef3f5c403e8]  
[2020-12-20 09:00:28,381: WARNING/ForkPoolWorker-7] 0.0009993846153846153
Unexpected problem with CA circuit to server "192.168.6.106:5064" was "Connection timed out" - disconnecting
CA.Client.Exception...............................................
    Warning: "Virtual circuit disconnect"
    Context: "192.168.6.106:5064"
    Source File: ../cac.cpp line 1237
    Current Time: Sun Dec 20 2020 11:12:38.155663952
..................................................................
Unexpected problem with CA circuit to server "192.168.6.106:5064" was "Connection timed out" - disconnecting
CA.Client.Exception...............................................
    Warning: "Virtual circuit disconnect"
    Context: "192.168.6.106:5064"
    Source File: ../cac.cpp line 1237
    Current Time: Sun Dec 20 2020 13:28:04.619050939
..................................................................
Unexpected problem with CA circuit to server "192.168.6.106:5064" was "Connection timed out" - disconnecting
CA.Client.Exception...............................................
    Warning: "Virtual circuit disconnect"
    Context: "192.168.6.106:5064"
    Source File: ../cac.cpp line 1237
    Current Time: Sun Dec 20 2020 15:43:31.083108540
..................................................................
Unexpected problem with CA circuit to server "192.168.6.106:5064" was "Connection timed out" - disconnecting
CA.Client.Exception...............................................
    Warning: "Virtual circuit disconnect"
    Context: "192.168.6.106:5064"
    Source File: ../cac.cpp line 1237
    Current Time: Sun Dec 20 2020 17:58:57.546922518
..................................................................
[2020-12-20 19:23:43,925: INFO/ForkPoolWorker-7] Task backend.main.tasks.accumulate_time[3cda0f5a-b1a3-4de8-b86b-4ef3f5c403e8] succeeded in 37395.58362294908s: None

worker: Warm shutdown (MainProcess)
Started at 2020-12-20 19:25:40
 
 -------------- celery@localhost.localdomain v5.0.2 (singularity)
--- ***** ----- 
-- ******* ---- Linux-5.8.11-200.fc32.x86_64-x86_64-with-glibc2.2.5 2020-12-20 19:25:41
- *** --- * --- 
- ** ---------- [config]
- ** ---------- .> app:         backend.main:0x7f9a6f30e7f0
- ** ---------- .> transport:   redis://localhost:6379//
- ** ---------- .> results:     redis://localhost:6379/
- *** --- * --- .> concurrency: 8 (prefork)
-- ******* ---- .> task events: OFF (enable -E to monitor tasks in this worker)
--- ***** ----- 
 -------------- [queues]
                .> celery           exchange=celery(direct) key=celery
                

[tasks]
  . backend.main.tasks.accumulate_time

[2020-12-20 19:25:41,465: INFO/MainProcess] Connected to redis://localhost:6379//
[2020-12-20 19:25:41,471: INFO/MainProcess] mingle: searching for neighbors
[2020-12-20 19:25:42,486: INFO/MainProcess] mingle: all alone
[2020-12-20 19:25:42,509: INFO/MainProcess] celery@localhost.localdomain ready.
[2020-12-20 19:26:03,582: INFO/MainProcess] Received task: backend.main.tasks.accumulate_time[01e3f088-bc17-4d28-bb42-b4e61df8e1f4]  
[2020-12-20 19:26:03,621: WARNING/ForkPoolWorker-7] 0.002
Unexpected problem with CA circuit to server "192.168.6.106:5064" was "Connection timed out" - disconnecting
CA.Client.Exception...............................................
    Warning: "Virtual circuit disconnect"
    Context: "192.168.6.106:5064"
    Source File: ../cac.cpp line 1237
    Current Time: Sun Dec 20 2020 21:41:46.891337802
..................................................................
Unexpected problem with CA circuit to server "192.168.6.106:5064" was "Connection timed out" - disconnecting
CA.Client.Exception...............................................
    Warning: "Virtual circuit disconnect"
    Context: "192.168.6.106:5064"
    Source File: ../cac.cpp line 1237
    Current Time: Sun Dec 20 2020 23:57:13.355118859
..................................................................
Unexpected problem with CA circuit to server "192.168.6.106:5064" was "Connection timed out" - disconnecting
CA.Client.Exception...............................................
    Warning: "Virtual circuit disconnect"
    Context: "192.168.6.106:5064"
    Source File: ../cac.cpp line 1237
    Current Time: Mon Dec 21 2020 02:12:39.818992631
..................................................................
Unexpected problem with CA circuit to server "192.168.6.106:5064" was "Connection timed out" - disconnecting
CA.Client.Exception...............................................
    Warning: "Virtual circuit disconnect"
    Context: "192.168.6.106:5064"
    Source File: ../cac.cpp line 1237
    Current Time: Mon Dec 21 2020 04:28:06.284078884
..................................................................
Unexpected problem with CA circuit to server "192.168.6.106:5064" was "Connection timed out" - disconnecting
CA.Client.Exception...............................................
    Warning: "Virtual circuit disconnect"
    Context: "192.168.6.106:5064"
    Source File: ../cac.cpp line 1237
    Current Time: Mon Dec 21 2020 06:43:32.748104795
..................................................................
[2020-12-21 08:30:00,730: ERROR/ForkPoolWorker-7] Task backend.main.tasks.accumulate_time[01e3f088-bc17-4d28-bb42-b4e61df8e1f4] raised unexpected: StatementError("(builtins.ValueError) could not convert string to float: 'None'")
Traceback (most recent call last):
  File "/usr/local/lib64/python3.8/site-packages/sqlalchemy/engine/base.py", line 1204, in _execute_context
    context = constructor(dialect, self, conn, *args)
  File "/usr/local/lib64/python3.8/site-packages/sqlalchemy/engine/default.py", line 839, in _init_compiled
    param.append(processors[key](compiled_params[key]))
ValueError: could not convert string to float: 'None'

The above exception was the direct cause of the following exception:

Traceback (most recent call last):
  File "/usr/local/lib/python3.8/site-packages/celery/app/trace.py", line 409, in trace_task
    R = retval = fun(*args, **kwargs)
  File "/home/linac/commissioning/lattice-setting/backend/main/celery_utils.py", line 9, in __call__
    call_res = TaskBase.__call__(self, *args, **kwargs)
  File "/usr/local/lib/python3.8/site-packages/celery/app/trace.py", line 701, in __protected_call__
    return self.run(*args, **kwargs)
  File "/home/linac/commissioning/lattice-setting/backend/main/tasks.py", line 164, in accumulate_time
    prev_time, timing_dict = timing_add_needed(current_time, prev_time,
  File "/home/linac/commissioning/lattice-setting/backend/main/tasks.py", line 101, in timing_add_needed
    save_timing(timing_dict)
  File "/home/linac/commissioning/lattice-setting/backend/main/tasks.py", line 37, in save_timing
    db.session.commit()
  File "/usr/local/lib64/python3.8/site-packages/sqlalchemy/orm/scoping.py", line 163, in do
    return getattr(self.registry(), name)(*args, **kwargs)
  File "/usr/local/lib64/python3.8/site-packages/sqlalchemy/orm/session.py", line 1042, in commit
    self.transaction.commit()
  File "/usr/local/lib64/python3.8/site-packages/sqlalchemy/orm/session.py", line 504, in commit
    self._prepare_impl()
  File "/usr/local/lib64/python3.8/site-packages/sqlalchemy/orm/session.py", line 483, in _prepare_impl
    self.session.flush()
  File "/usr/local/lib64/python3.8/site-packages/sqlalchemy/orm/session.py", line 2536, in flush
    self._flush(objects)
  File "/usr/local/lib64/python3.8/site-packages/sqlalchemy/orm/session.py", line 2678, in _flush
    transaction.rollback(_capture_exception=True)
  File "/usr/local/lib64/python3.8/site-packages/sqlalchemy/util/langhelpers.py", line 68, in __exit__
    compat.raise_(
  File "/usr/local/lib64/python3.8/site-packages/sqlalchemy/util/compat.py", line 182, in raise_
    raise exception
  File "/usr/local/lib64/python3.8/site-packages/sqlalchemy/orm/session.py", line 2638, in _flush
    flush_context.execute()
  File "/usr/local/lib64/python3.8/site-packages/sqlalchemy/orm/unitofwork.py", line 422, in execute
    rec.execute(self)
  File "/usr/local/lib64/python3.8/site-packages/sqlalchemy/orm/unitofwork.py", line 586, in execute
    persistence.save_obj(
  File "/usr/local/lib64/python3.8/site-packages/sqlalchemy/orm/persistence.py", line 239, in save_obj
    _emit_insert_statements(
  File "/usr/local/lib64/python3.8/site-packages/sqlalchemy/orm/persistence.py", line 1135, in _emit_insert_statements
    result = cached_connections[connection].execute(
  File "/usr/local/lib64/python3.8/site-packages/sqlalchemy/engine/base.py", line 1011, in execute
    return meth(self, multiparams, params)
  File "/usr/local/lib64/python3.8/site-packages/sqlalchemy/sql/elements.py", line 298, in _execute_on_connection
    return connection._execute_clauseelement(self, multiparams, params)
  File "/usr/local/lib64/python3.8/site-packages/sqlalchemy/engine/base.py", line 1124, in _execute_clauseelement
    ret = self._execute_context(
  File "/usr/local/lib64/python3.8/site-packages/sqlalchemy/engine/base.py", line 1206, in _execute_context
    self._handle_dbapi_exception(
  File "/usr/local/lib64/python3.8/site-packages/sqlalchemy/engine/base.py", line 1510, in _handle_dbapi_exception
    util.raise_(
  File "/usr/local/lib64/python3.8/site-packages/sqlalchemy/util/compat.py", line 182, in raise_
    raise exception
  File "/usr/local/lib64/python3.8/site-packages/sqlalchemy/engine/base.py", line 1204, in _execute_context
    context = constructor(dialect, self, conn, *args)
  File "/usr/local/lib64/python3.8/site-packages/sqlalchemy/engine/default.py", line 839, in _init_compiled
    param.append(processors[key](compiled_params[key]))
sqlalchemy.exc.StatementError: (builtins.ValueError) could not convert string to float: 'None'
[SQL: INSERT INTO timing (timestamp, dutyfactor, times, acct1, acct2, acct3, acct4) VALUES (?, ?, ?, ?, ?, ?, ?)]
[parameters: [{'acct2': 0, 'acct3': 0, 'dutyfactor': 'None', 'acct4': 0, 'acct1': 0, 'times': 0}]]
Unexpected problem with CA circuit to server "192.168.6.106:5064" was "Connection timed out" - disconnecting
CA.Client.Exception...............................................
    Warning: "Virtual circuit disconnect"
    Context: "192.168.6.106:5064"
    Source File: ../cac.cpp line 1237
    Current Time: Mon Dec 21 2020 08:58:59.211001176
..................................................................
Unexpected problem with CA circuit to server "192.168.6.106:5064" was "Connection reset by peer" - disconnecting
CA.Client.Exception...............................................
    Warning: "Virtual circuit disconnect"
    Context: "192.168.6.106:5064"
    Source File: ../cac.cpp line 1237
    Current Time: Mon Dec 21 2020 09:52:06.262548726
..................................................................
CA.Client.Exception...............................................
    Warning: "Virtual circuit disconnect"
    Context: "192.168.6.106:5064"
    Source File: ../cac.cpp line 1237
    Current Time: Mon Dec 21 2020 10:06:27.698715990
..................................................................
Unexpected problem with CA circuit to server "192.168.6.106:5064" was "Connection timed out" - disconnecting
CA.Client.Exception...............................................
    Warning: "Virtual circuit disconnect"
    Context: "192.168.6.106:5064"
    Source File: ../cac.cpp line 1237
    Current Time: Mon Dec 21 2020 12:21:40.236040315
..................................................................
Unexpected problem with CA circuit to server "192.168.6.106:5064" was "Connection timed out" - disconnecting
CA.Client.Exception...............................................
    Warning: "Virtual circuit disconnect"
    Context: "192.168.6.106:5064"
    Source File: ../cac.cpp line 1237
    Current Time: Mon Dec 21 2020 14:35:24.299002621
..................................................................
Unexpected problem with CA circuit to server "192.168.6.106:5064" was "Connection timed out" - disconnecting
CA.Client.Exception...............................................
    Warning: "Virtual circuit disconnect"
    Context: "192.168.6.106:5064"
    Source File: ../cac.cpp line 1237
    Current Time: Mon Dec 21 2020 16:50:50.763103681
..................................................................
Unexpected problem with CA circuit to server "192.168.6.106:5064" was "Connection timed out" - disconnecting
CA.Client.Exception...............................................
    Warning: "Virtual circuit disconnect"
    Context: "192.168.6.106:5064"
    Source File: ../cac.cpp line 1237
    Current Time: Mon Dec 21 2020 19:06:17.228095783
..................................................................
Unexpected problem with CA circuit to server "192.168.6.106:5064" was "Connection timed out" - disconnecting
CA.Client.Exception...............................................
    Warning: "Virtual circuit disconnect"
    Context: "192.168.6.106:5064"
    Source File: ../cac.cpp line 1237
    Current Time: Mon Dec 21 2020 21:21:43.691063679
..................................................................
Unexpected problem with CA circuit to server "192.168.6.106:5064" was "Connection timed out" - disconnecting
CA.Client.Exception...............................................
    Warning: "Virtual circuit disconnect"
    Context: "192.168.6.106:5064"
    Source File: ../cac.cpp line 1237
    Current Time: Tue Dec 22 2020 00:25:13.738987134
..................................................................
Unexpected problem with CA circuit to server "192.168.6.106:5064" was "Connection timed out" - disconnecting
CA.Client.Exception...............................................
    Warning: "Virtual circuit disconnect"
    Context: "192.168.6.106:5064"
    Source File: ../cac.cpp line 1237
    Current Time: Tue Dec 22 2020 02:40:40.203094464
..................................................................
Unexpected problem with CA circuit to server "192.168.6.106:5064" was "Connection timed out" - disconnecting
CA.Client.Exception...............................................
    Warning: "Virtual circuit disconnect"
    Context: "192.168.6.106:5064"
    Source File: ../cac.cpp line 1237
    Current Time: Tue Dec 22 2020 04:56:06.666998340
..................................................................
Unexpected problem with CA circuit to server "192.168.6.106:5064" was "Connection timed out" - disconnecting
CA.Client.Exception...............................................
    Warning: "Virtual circuit disconnect"
    Context: "192.168.6.106:5064"
    Source File: ../cac.cpp line 1237
    Current Time: Tue Dec 22 2020 07:11:33.131013357
..................................................................
Unexpected problem with CA circuit to server "192.168.6.106:5064" was "Connection timed out" - disconnecting
CA.Client.Exception...............................................
    Warning: "Virtual circuit disconnect"
    Context: "192.168.6.106:5064"
    Source File: ../cac.cpp line 1237
    Current Time: Tue Dec 22 2020 09:26:59.595074338
..................................................................
Unexpected problem with CA circuit to server "192.168.6.106:5064" was "Connection timed out" - disconnecting
CA.Client.Exception...............................................
    Warning: "Virtual circuit disconnect"
    Context: "192.168.6.106:5064"
    Source File: ../cac.cpp line 1237
    Current Time: Tue Dec 22 2020 11:42:26.059075063
..................................................................
Unexpected problem with CA circuit to server "192.168.6.106:5064" was "Connection timed out" - disconnecting
CA.Client.Exception...............................................
    Warning: "Virtual circuit disconnect"
    Context: "192.168.6.106:5064"
    Source File: ../cac.cpp line 1237
    Current Time: Tue Dec 22 2020 13:57:52.523094162
..................................................................
Unexpected problem with CA circuit to server "192.168.6.106:5064" was "Connection timed out" - disconnecting
CA.Client.Exception...............................................
    Warning: "Virtual circuit disconnect"
    Context: "192.168.6.106:5064"
    Source File: ../cac.cpp line 1237
    Current Time: Tue Dec 22 2020 17:10:06.859100618
..................................................................
Unexpected problem with CA circuit to server "192.168.6.106:5064" was "Connection timed out" - disconnecting
CA.Client.Exception...............................................
    Warning: "Virtual circuit disconnect"
    Context: "192.168.6.106:5064"
    Source File: ../cac.cpp line 1237
    Current Time: Tue Dec 22 2020 19:25:33.324075327
..................................................................
Unexpected problem with CA circuit to server "192.168.6.106:5064" was "Connection timed out" - disconnecting
CA.Client.Exception...............................................
    Warning: "Virtual circuit disconnect"
    Context: "192.168.6.106:5064"
    Source File: ../cac.cpp line 1237
    Current Time: Tue Dec 22 2020 21:40:59.787116053
..................................................................
Unexpected problem with CA circuit to server "192.168.6.106:5064" was "Connection timed out" - disconnecting
CA.Client.Exception...............................................
    Warning: "Virtual circuit disconnect"
    Context: "192.168.6.106:5064"
    Source File: ../cac.cpp line 1237
    Current Time: Tue Dec 22 2020 23:56:26.251058019
..................................................................
Unexpected problem with CA circuit to server "192.168.6.106:5064" was "Connection timed out" - disconnecting
CA.Client.Exception...............................................
    Warning: "Virtual circuit disconnect"
    Context: "192.168.6.106:5064"
    Source File: ../cac.cpp line 1237
    Current Time: Wed Dec 23 2020 02:11:52.715118269
..................................................................
Unexpected problem with CA circuit to server "192.168.6.106:5064" was "Connection timed out" - disconnecting
CA.Client.Exception...............................................
    Warning: "Virtual circuit disconnect"
    Context: "192.168.6.106:5064"
    Source File: ../cac.cpp line 1237
    Current Time: Wed Dec 23 2020 04:27:19.179096388
..................................................................
Unexpected problem with CA circuit to server "192.168.6.106:5064" was "Connection timed out" - disconnecting
CA.Client.Exception...............................................
    Warning: "Virtual circuit disconnect"
    Context: "192.168.6.106:5064"
    Source File: ../cac.cpp line 1237
    Current Time: Wed Dec 23 2020 06:42:45.642964634
..................................................................
Unexpected problem with CA circuit to server "192.168.6.106:5064" was "Connection timed out" - disconnecting
CA.Client.Exception...............................................
    Warning: "Virtual circuit disconnect"
    Context: "192.168.6.106:5064"
    Source File: ../cac.cpp line 1237
    Current Time: Wed Dec 23 2020 08:58:12.107013713
..................................................................
Unexpected problem with CA circuit to server "192.168.6.106:5064" was "Connection timed out" - disconnecting
CA.Client.Exception...............................................
    Warning: "Virtual circuit disconnect"
    Context: "192.168.6.106:5064"
    Source File: ../cac.cpp line 1237
    Current Time: Wed Dec 23 2020 11:13:38.571036697
..................................................................
Unexpected problem with CA circuit to server "192.168.6.106:5064" was "Connection timed out" - disconnecting
CA.Client.Exception...............................................
    Warning: "Virtual circuit disconnect"
    Context: "192.168.6.106:5064"
    Source File: ../cac.cpp line 1237
    Current Time: Wed Dec 23 2020 13:29:05.035024972
..................................................................
Unexpected problem with CA circuit to server "192.168.6.106:5064" was "Connection timed out" - disconnecting
CA.Client.Exception...............................................
    Warning: "Virtual circuit disconnect"
    Context: "192.168.6.106:5064"
    Source File: ../cac.cpp line 1237
    Current Time: Wed Dec 23 2020 15:44:31.498987599
..................................................................
Unexpected problem with CA circuit to server "192.168.6.106:5064" was "Connection timed out" - disconnecting
CA.Client.Exception...............................................
    Warning: "Virtual circuit disconnect"
    Context: "192.168.6.106:5064"
    Source File: ../cac.cpp line 1237
    Current Time: Wed Dec 23 2020 17:59:57.964142003
..................................................................
Unexpected problem with CA circuit to server "192.168.6.106:5064" was "Connection timed out" - disconnecting
CA.Client.Exception...............................................
    Warning: "Virtual circuit disconnect"
    Context: "192.168.6.106:5064"
    Source File: ../cac.cpp line 1237
    Current Time: Wed Dec 23 2020 20:15:24.427060863
..................................................................
Unexpected problem with CA circuit to server "192.168.6.106:5064" was "Connection timed out" - disconnecting
CA.Client.Exception...............................................
    Warning: "Virtual circuit disconnect"
    Context: "192.168.6.106:5064"
    Source File: ../cac.cpp line 1237
    Current Time: Wed Dec 23 2020 22:30:50.891016277
..................................................................
Unexpected problem with CA circuit to server "192.168.6.106:5064" was "Connection timed out" - disconnecting
CA.Client.Exception...............................................
    Warning: "Virtual circuit disconnect"
    Context: "192.168.6.106:5064"
    Source File: ../cac.cpp line 1237
    Current Time: Thu Dec 24 2020 00:46:17.355105047
..................................................................
Unexpected problem with CA circuit to server "192.168.6.106:5064" was "Connection timed out" - disconnecting
CA.Client.Exception...............................................
    Warning: "Virtual circuit disconnect"
    Context: "192.168.6.106:5064"
    Source File: ../cac.cpp line 1237
    Current Time: Thu Dec 24 2020 03:01:43.819024100
..................................................................
Unexpected problem with CA circuit to server "192.168.6.106:5064" was "Connection timed out" - disconnecting
CA.Client.Exception...............................................
    Warning: "Virtual circuit disconnect"
    Context: "192.168.6.106:5064"
    Source File: ../cac.cpp line 1237
    Current Time: Thu Dec 24 2020 05:17:10.284111312
..................................................................
Unexpected problem with CA circuit to server "192.168.6.106:5064" was "Connection timed out" - disconnecting
CA.Client.Exception...............................................
    Warning: "Virtual circuit disconnect"
    Context: "192.168.6.106:5064"
    Source File: ../cac.cpp line 1237
    Current Time: Thu Dec 24 2020 07:32:36.747019522
..................................................................
Unexpected problem with CA circuit to server "192.168.6.106:5064" was "Connection timed out" - disconnecting
CA.Client.Exception...............................................
    Warning: "Virtual circuit disconnect"
    Context: "192.168.6.106:5064"
    Source File: ../cac.cpp line 1237
    Current Time: Thu Dec 24 2020 09:48:03.211078759
..................................................................
Unexpected problem with CA circuit to server "192.168.6.106:5064" was "Connection timed out" - disconnecting
CA.Client.Exception...............................................
    Warning: "Virtual circuit disconnect"
    Context: "192.168.6.106:5064"
    Source File: ../cac.cpp line 1237
    Current Time: Thu Dec 24 2020 12:03:29.675028791
..................................................................
Unexpected problem with CA circuit to server "192.168.6.106:5064" was "Connection timed out" - disconnecting
CA.Client.Exception...............................................
    Warning: "Virtual circuit disconnect"
    Context: "192.168.6.106:5064"
    Source File: ../cac.cpp line 1237
    Current Time: Thu Dec 24 2020 14:18:56.139072838
..................................................................
Unexpected problem with CA circuit to server "192.168.6.106:5064" was "Connection timed out" - disconnecting
CA.Client.Exception...............................................
    Warning: "Virtual circuit disconnect"
    Context: "192.168.6.106:5064"
    Source File: ../cac.cpp line 1237
    Current Time: Thu Dec 24 2020 16:34:22.603090188
..................................................................
Unexpected problem with CA circuit to server "192.168.6.106:5064" was "Connection timed out" - disconnecting
CA.Client.Exception...............................................
    Warning: "Virtual circuit disconnect"
    Context: "192.168.6.106:5064"
    Source File: ../cac.cpp line 1237
    Current Time: Thu Dec 24 2020 18:49:49.066946149
..................................................................
Unexpected problem with CA circuit to server "192.168.6.106:5064" was "Connection timed out" - disconnecting
CA.Client.Exception...............................................
    Warning: "Virtual circuit disconnect"
    Context: "192.168.6.106:5064"
    Source File: ../cac.cpp line 1237
    Current Time: Thu Dec 24 2020 21:05:15.531059788
..................................................................
Unexpected problem with CA circuit to server "192.168.6.106:5064" was "Connection timed out" - disconnecting
CA.Client.Exception...............................................
    Warning: "Virtual circuit disconnect"
    Context: "192.168.6.106:5064"
    Source File: ../cac.cpp line 1237
    Current Time: Thu Dec 24 2020 23:26:42.443992635
..................................................................
Unexpected problem with CA circuit to server "192.168.6.106:5064" was "Connection timed out" - disconnecting
CA.Client.Exception...............................................
    Warning: "Virtual circuit disconnect"
    Context: "192.168.6.106:5064"
    Source File: ../cac.cpp line 1237
    Current Time: Fri Dec 25 2020 01:40:30.603071549
..................................................................
Unexpected problem with CA circuit to server "192.168.6.106:5064" was "Connection timed out" - disconnecting
CA.Client.Exception...............................................
    Warning: "Virtual circuit disconnect"
    Context: "192.168.6.106:5064"
    Source File: ../cac.cpp line 1237
    Current Time: Fri Dec 25 2020 03:57:06.699989507
..................................................................
Unexpected problem with CA circuit to server "192.168.6.106:5064" was "Connection timed out" - disconnecting
CA.Client.Exception...............................................
    Warning: "Virtual circuit disconnect"
    Context: "192.168.6.106:5064"
    Source File: ../cac.cpp line 1237
    Current Time: Fri Dec 25 2020 06:11:23.532031488
..................................................................
Unexpected problem with CA circuit to server "192.168.6.106:5064" was "Connection timed out" - disconnecting
CA.Client.Exception...............................................
    Warning: "Virtual circuit disconnect"
    Context: "192.168.6.106:5064"
    Source File: ../cac.cpp line 1237
    Current Time: Fri Dec 25 2020 08:26:49.995110512
..................................................................

worker: Warm shutdown (MainProcess)
Started at 2020-12-25 08:47:01
 
 -------------- celery@localhost.localdomain v5.0.2 (singularity)
--- ***** ----- 
-- ******* ---- Linux-5.8.11-200.fc32.x86_64-x86_64-with-glibc2.2.5 2020-12-25 08:47:02
- *** --- * --- 
- ** ---------- [config]
- ** ---------- .> app:         backend.main:0x7f1ddb7867f0
- ** ---------- .> transport:   redis://localhost:6379//
- ** ---------- .> results:     redis://localhost:6379/
- *** --- * --- .> concurrency: 8 (prefork)
-- ******* ---- .> task events: OFF (enable -E to monitor tasks in this worker)
--- ***** ----- 
 -------------- [queues]
                .> celery           exchange=celery(direct) key=celery
                

[tasks]
  . backend.main.tasks.accumulate_time

[2020-12-25 08:47:02,655: INFO/MainProcess] Connected to redis://localhost:6379//
[2020-12-25 08:47:02,661: INFO/MainProcess] mingle: searching for neighbors
[2020-12-25 08:47:03,673: INFO/MainProcess] mingle: all alone
[2020-12-25 08:47:03,680: INFO/MainProcess] celery@localhost.localdomain ready.
[2020-12-25 08:47:10,604: INFO/MainProcess] Received task: backend.main.tasks.accumulate_time[5735e0b0-d499-420d-ac24-a63e8d4649b0]  
[2020-12-25 08:47:10,645: ERROR/ForkPoolWorker-7] Task backend.main.tasks.accumulate_time[5735e0b0-d499-420d-ac24-a63e8d4649b0] raised unexpected: KeyError('duty_factor')
Traceback (most recent call last):
  File "/usr/local/lib/python3.8/site-packages/celery/app/trace.py", line 409, in trace_task
    R = retval = fun(*args, **kwargs)
  File "/home/linac/commissioning/lattice-setting/backend/main/celery_utils.py", line 9, in __call__
    call_res = TaskBase.__call__(self, *args, **kwargs)
  File "/usr/local/lib/python3.8/site-packages/celery/app/trace.py", line 701, in __protected_call__
    return self.run(*args, **kwargs)
  File "/home/linac/commissioning/lattice-setting/backend/main/tasks.py", line 133, in accumulate_time
    duty_factor = str(monitor_values['duty_factor'])
KeyError: 'duty_factor'

worker: Warm shutdown (MainProcess)
Started at 2020-12-25 08:52:07
 
 -------------- celery@localhost.localdomain v5.0.2 (singularity)
--- ***** ----- 
-- ******* ---- Linux-5.8.11-200.fc32.x86_64-x86_64-with-glibc2.2.5 2020-12-25 08:52:07
- *** --- * --- 
- ** ---------- [config]
- ** ---------- .> app:         backend.main:0x7ffaf9fdb7f0
- ** ---------- .> transport:   redis://localhost:6379//
- ** ---------- .> results:     redis://localhost:6379/
- *** --- * --- .> concurrency: 8 (prefork)
-- ******* ---- .> task events: OFF (enable -E to monitor tasks in this worker)
--- ***** ----- 
 -------------- [queues]
                .> celery           exchange=celery(direct) key=celery
                

[tasks]
  . backend.main.tasks.accumulate_time

[2020-12-25 08:52:07,948: INFO/MainProcess] Connected to redis://localhost:6379//
[2020-12-25 08:52:07,954: INFO/MainProcess] mingle: searching for neighbors
[2020-12-25 08:52:08,967: INFO/MainProcess] mingle: all alone
[2020-12-25 08:52:08,987: INFO/MainProcess] celery@localhost.localdomain ready.
[2020-12-25 08:58:41,479: INFO/MainProcess] Received task: backend.main.tasks.accumulate_time[ac3e3069-9347-4ba2-b3da-bf477b8636e1]  
